2024-04-14T16:25:55 {"cpu": 0.2412109375, "cpu_total": 8, "cpu_usage": 0.0301513671875, "memory": 3408.0, "memory_total": 9922.0, "memory_usage": 0.34347913727071155, "pipeline_run_id": 3, "pipeline_schedule_id": 3, "pipeline_uuid": "seed_bq", "hostname": "78c121f5c730", "level": "INFO", "message": "Pipeline seed_bq for run 3 in schedule 3 is alive.", "timestamp": 1713111955.565702, "uuid": "5d252e4bcd954d798c6767d7f696dfd4"}
2024-04-14T16:25:55 {"block_run_id": 5, "block_uuid": "api_to_bigquery", "pipeline_run_id": 3, "pipeline_schedule_id": 3, "pipeline_uuid": "seed_bq", "hostname": "78c121f5c730", "level": "INFO", "message": "Execute PipelineRun 3, BlockRun 5: pipeline seed_bq block api_to_bigquery", "timestamp": 1713111955.965321, "uuid": "3e81398c6ab4484d90a421e79eb8971a"}
2024-04-14T16:25:55 {"cpu": 0.2412109375, "cpu_total": 8, "cpu_usage": 0.0301513671875, "memory": 3452.0, "memory_total": 9922.0, "memory_usage": 0.34791372707115503, "pipeline_run_id": 3, "pipeline_schedule_id": 3, "pipeline_uuid": "seed_bq", "hostname": "78c121f5c730", "level": "INFO", "message": "Pipeline seed_bq for run 3 in schedule 3 is alive.", "timestamp": 1713111955.998229, "uuid": "8e826a206438449fa8f5850306dc400b"}
2024-04-14T16:25:56 {"block_run_id": 6, "block_uuid": "load_daily_schedule", "pipeline_run_id": 3, "pipeline_schedule_id": 3, "pipeline_uuid": "seed_bq", "hostname": "78c121f5c730", "level": "INFO", "message": "Execute PipelineRun 3, BlockRun 6: pipeline seed_bq block load_daily_schedule", "timestamp": 1713111956.947784, "uuid": "5225173b31d64e8296ac726e72311977"}
2024-04-14T16:26:05 {"cpu": 0.23828125, "cpu_total": 8, "cpu_usage": 0.02978515625, "memory": 3840.0, "memory_total": 9922.0, "memory_usage": 0.38701874622052007, "pipeline_run_id": 3, "pipeline_schedule_id": 3, "pipeline_uuid": "seed_bq", "hostname": "78c121f5c730", "level": "INFO", "message": "Pipeline seed_bq for run 3 in schedule 3 is alive.", "timestamp": 1713111965.473598, "uuid": "6c9b4ec843734f00b417d34fd1cab335"}
2024-04-14T16:26:13 {"block_run_id": 6, "block_uuid": "load_daily_schedule", "pipeline_run_id": 3, "pipeline_schedule_id": 3, "pipeline_uuid": "seed_bq", "hostname": "78c121f5c730", "level": "INFO", "message": "BlockRun 6 (block_uuid: load_daily_schedule) completes.", "timestamp": 1713111973.773996, "uuid": "326f9a4cd8434ba586d7dccfcc392bdc"}
2024-04-14T16:26:16 {"cpu": 0.251953125, "cpu_total": 8, "cpu_usage": 0.031494140625, "memory": 3636.0, "memory_total": 9922.0, "memory_usage": 0.36645837532755493, "pipeline_run_id": 3, "pipeline_schedule_id": 3, "pipeline_uuid": "seed_bq", "hostname": "78c121f5c730", "level": "INFO", "message": "Pipeline seed_bq for run 3 in schedule 3 is alive.", "timestamp": 1713111976.094926, "uuid": "3e0630aed9f941458e4a6f1d89442b10"}
2024-04-14T16:26:25 {"cpu": 0.2822265625, "cpu_total": 8, "cpu_usage": 0.0352783203125, "memory": 3636.0, "memory_total": 9922.0, "memory_usage": 0.36645837532755493, "pipeline_run_id": 3, "pipeline_schedule_id": 3, "pipeline_uuid": "seed_bq", "hostname": "78c121f5c730", "level": "INFO", "message": "Pipeline seed_bq for run 3 in schedule 3 is alive.", "timestamp": 1713111985.65868, "uuid": "a6176c8ad6c743658f8b11888f4f214f"}
2024-04-14T16:26:27 {"block_run_id": 5, "block_uuid": "api_to_bigquery", "pipeline_run_id": 3, "pipeline_schedule_id": 3, "pipeline_uuid": "seed_bq", "hostname": "78c121f5c730", "level": "EXCEPTION", "message": "BlockRun 5 (block_uuid: api_to_bigquery) failed.", "timestamp": 1713111987.084888, "uuid": "3404d86d8ca248babf96b57e48b5fbd5", "error": ["Traceback (most recent call last):\n  File \"/usr/local/lib/python3.10/site-packages/pandas/core/indexes/base.py\", line 3802, in get_loc\n    return self._engine.get_loc(casted_key)\n  File \"index.pyx\", line 153, in pandas._libs.index.IndexEngine.get_loc\n  File \"index.pyx\", line 182, in pandas._libs.index.IndexEngine.get_loc\n  File \"pandas/_libs/hashtable_class_helper.pxi\", line 7081, in pandas._libs.hashtable.PyObjectHashTable.get_item\n  File \"pandas/_libs/hashtable_class_helper.pxi\", line 7089, in pandas._libs.hashtable.PyObjectHashTable.get_item\nKeyError: 'standingsdate'\n\nThe above exception was the direct cause of the following exception:\n\nTraceback (most recent call last):\n  File \"/home/src/./mage_nba_watchability_index/utils/dlt_resources/dlt_nba.py\", line 124, in load_daily_standings\n    ec['standingsdate'] = pd.to_datetime(ec['standingsdate'], format=\"%d/%m/%Y\")\n  File \"/usr/local/lib/python3.10/site-packages/pandas/core/frame.py\", line 4090, in __getitem__\n    indexer = self.columns.get_loc(key)\n  File \"/usr/local/lib/python3.10/site-packages/pandas/core/indexes/base.py\", line 3809, in get_loc\n    raise KeyError(key) from err\nKeyError: 'standingsdate'\n\nDuring handling of the above exception, another exception occurred:\n\nTraceback (most recent call last):\n  File \"/usr/local/lib/python3.10/site-packages/pandas/core/indexes/base.py\", line 3802, in get_loc\n    return self._engine.get_loc(casted_key)\n  File \"index.pyx\", line 153, in pandas._libs.index.IndexEngine.get_loc\n  File \"index.pyx\", line 182, in pandas._libs.index.IndexEngine.get_loc\n  File \"pandas/_libs/hashtable_class_helper.pxi\", line 7081, in pandas._libs.hashtable.PyObjectHashTable.get_item\n  File \"pandas/_libs/hashtable_class_helper.pxi\", line 7089, in pandas._libs.hashtable.PyObjectHashTable.get_item\nKeyError: 'standingsdate'\n\nThe above exception was the direct cause of the following exception:\n\nTraceback (most recent call last):\n  File \"/usr/local/lib/python3.10/site-packages/dlt/extract/pipe.py\", line 837, in _get_source_item\n    if (item := next(gen)) is not None:\n  File \"/home/src/./mage_nba_watchability_index/utils/dlt_resources/dlt_nba.py\", line 148, in load_daily_standings\n    ec['standingsdate'] = pd.to_datetime(ec['standingsdate'], format=\"%d/%m/%Y\")\n  File \"/usr/local/lib/python3.10/site-packages/pandas/core/frame.py\", line 4090, in __getitem__\n    indexer = self.columns.get_loc(key)\n  File \"/usr/local/lib/python3.10/site-packages/pandas/core/indexes/base.py\", line 3809, in get_loc\n    raise KeyError(key) from err\nKeyError: 'standingsdate'\n\nThe above exception was the direct cause of the following exception:\n\nTraceback (most recent call last):\n  File \"/usr/local/lib/python3.10/site-packages/dlt/pipeline/pipeline.py\", line 391, in extract\n    self._extract_source(extract_step, source, max_parallel_items, workers)\n  File \"/usr/local/lib/python3.10/site-packages/dlt/pipeline/pipeline.py\", line 1028, in _extract_source\n    load_id = extract.extract(source, max_parallel_items, workers)\n  File \"/usr/local/lib/python3.10/site-packages/dlt/extract/extract.py\", line 341, in extract\n    self._extract_single_source(\n  File \"/usr/local/lib/python3.10/site-packages/dlt/extract/extract.py\", line 271, in _extract_single_source\n    for pipe_item in pipes:\n  File \"/usr/local/lib/python3.10/site-packages/dlt/extract/pipe.py\", line 605, in __next__\n    pipe_item = self._get_source_item()\n  File \"/usr/local/lib/python3.10/site-packages/dlt/extract/pipe.py\", line 863, in _get_source_item\n    raise ResourceExtractionError(pipe.name, gen, str(ex), \"generator\") from ex\ndlt.extract.exceptions.ResourceExtractionError: In processing pipe src_daily_standings: extraction of resource src_daily_standings in generator load_daily_standings caused an exception: 'standingsdate'\n\nThe above exception was the direct cause of the following exception:\n\nTraceback (most recent call last):\n  File \"/usr/local/lib/python3.10/site-packages/mage_ai/data_preparation/executors/block_executor.py\", line 612, in execute\n    result = __execute_with_retry()\n  File \"/usr/local/lib/python3.10/site-packages/mage_ai/shared/retry.py\", line 54, in retry_func\n    raise e\n  File \"/usr/local/lib/python3.10/site-packages/mage_ai/shared/retry.py\", line 38, in retry_func\n    return func(*args, **kwargs)\n  File \"/usr/local/lib/python3.10/site-packages/mage_ai/data_preparation/executors/block_executor.py\", line 587, in __execute_with_retry\n    return self._execute(\n  File \"/usr/local/lib/python3.10/site-packages/mage_ai/data_preparation/executors/block_executor.py\", line 1075, in _execute\n    result = self.block.execute_sync(\n  File \"/usr/local/lib/python3.10/site-packages/mage_ai/data_preparation/models/block/__init__.py\", line 1312, in execute_sync\n    raise err\n  File \"/usr/local/lib/python3.10/site-packages/mage_ai/data_preparation/models/block/__init__.py\", line 1221, in execute_sync\n    output = self.execute_block(\n  File \"/usr/local/lib/python3.10/site-packages/mage_ai/data_preparation/models/block/__init__.py\", line 1527, in execute_block\n    outputs = self._execute_block(\n  File \"/usr/local/lib/python3.10/site-packages/mage_ai/data_preparation/models/block/__init__.py\", line 1683, in _execute_block\n    outputs = self.execute_block_function(\n  File \"/usr/local/lib/python3.10/site-packages/mage_ai/data_preparation/models/block/__init__.py\", line 1722, in execute_block_function\n    output = block_function_updated(*input_vars, **global_vars)\n  File \"<string>\", line 58, in load_data\n  File \"/usr/local/lib/python3.10/site-packages/dlt/pipeline/pipeline.py\", line 193, in _wrap\n    step_info = f(self, *args, **kwargs)\n  File \"/usr/local/lib/python3.10/site-packages/dlt/pipeline/pipeline.py\", line 238, in _wrap\n    return f(self, *args, **kwargs)\n  File \"/usr/local/lib/python3.10/site-packages/dlt/pipeline/pipeline.py\", line 619, in run\n    self.extract(\n  File \"/usr/local/lib/python3.10/site-packages/dlt/pipeline/pipeline.py\", line 193, in _wrap\n    step_info = f(self, *args, **kwargs)\n  File \"/usr/local/lib/python3.10/site-packages/dlt/pipeline/pipeline.py\", line 164, in _wrap\n    rv = f(self, *args, **kwargs)\n  File \"/usr/local/lib/python3.10/site-packages/dlt/pipeline/pipeline.py\", line 151, in _wrap\n    return f(self, *args, **kwargs)\n  File \"/usr/local/lib/python3.10/site-packages/dlt/pipeline/pipeline.py\", line 238, in _wrap\n    return f(self, *args, **kwargs)\n  File \"/usr/local/lib/python3.10/site-packages/dlt/pipeline/pipeline.py\", line 403, in extract\n    raise PipelineStepFailed(\ndlt.pipeline.exceptions.PipelineStepFailed: Pipeline execution failed at stage extract when processing package 1713111985.9029875 with exception:\n\n<class 'dlt.extract.exceptions.ResourceExtractionError'>\nIn processing pipe src_daily_standings: extraction of resource src_daily_standings in generator load_daily_standings caused an exception: 'standingsdate'\n"], "error_stack": [["  File \"/usr/local/bin/mage\", line 8, in <module>\n    sys.exit(app())\n", "  File \"/usr/local/lib/python3.10/site-packages/typer/main.py\", line 311, in __call__\n    return get_command(self)(*args, **kwargs)\n", "  File \"/usr/local/lib/python3.10/site-packages/click/core.py\", line 1130, in __call__\n    return self.main(*args, **kwargs)\n", "  File \"/usr/local/lib/python3.10/site-packages/typer/core.py\", line 778, in main\n    return _main(\n", "  File \"/usr/local/lib/python3.10/site-packages/typer/core.py\", line 216, in _main\n    rv = self.invoke(ctx)\n", "  File \"/usr/local/lib/python3.10/site-packages/click/core.py\", line 1657, in invoke\n    return _process_result(sub_ctx.command.invoke(sub_ctx))\n", "  File \"/usr/local/lib/python3.10/site-packages/click/core.py\", line 1404, in invoke\n    return ctx.invoke(self.callback, **ctx.params)\n", "  File \"/usr/local/lib/python3.10/site-packages/click/core.py\", line 760, in invoke\n    return __callback(*args, **kwargs)\n", "  File \"/usr/local/lib/python3.10/site-packages/typer/main.py\", line 683, in wrapper\n    return callback(**use_params)  # type: ignore\n", "  File \"/usr/local/lib/python3.10/site-packages/mage_ai/cli/main.py\", line 163, in start\n    start_server(\n", "  File \"/usr/local/lib/python3.10/site-packages/mage_ai/server/server.py\", line 659, in start_server\n    scheduler_manager.start_scheduler()\n", "  File \"/usr/local/lib/python3.10/site-packages/mage_ai/server/scheduler_manager.py\", line 87, in start_scheduler\n    proc.start()\n", "  File \"/usr/local/lib/python3.10/multiprocessing/process.py\", line 121, in start\n    self._popen = self._Popen(self)\n", "  File \"/usr/local/lib/python3.10/multiprocessing/context.py\", line 224, in _Popen\n    return _default_context.get_context().Process._Popen(process_obj)\n", "  File \"/usr/local/lib/python3.10/multiprocessing/context.py\", line 281, in _Popen\n    return Popen(process_obj)\n", "  File \"/usr/local/lib/python3.10/multiprocessing/popen_fork.py\", line 19, in __init__\n    self._launch(process_obj)\n", "  File \"/usr/local/lib/python3.10/multiprocessing/popen_fork.py\", line 71, in _launch\n    code = process_obj._bootstrap(parent_sentinel=child_r)\n", "  File \"/usr/local/lib/python3.10/multiprocessing/process.py\", line 314, in _bootstrap\n    self.run()\n", "  File \"/usr/local/lib/python3.10/multiprocessing/process.py\", line 108, in run\n    self._target(*self._args, **self._kwargs)\n", "  File \"/usr/local/lib/python3.10/site-packages/mage_ai/orchestration/db/process.py\", line 15, in start_session_and_run\n    results = target(*args)\n", "  File \"/usr/local/lib/python3.10/site-packages/mage_ai/server/scheduler_manager.py\", line 50, in run_scheduler\n    LoopTimeTrigger().start()\n", "  File \"/usr/local/lib/python3.10/site-packages/mage_ai/orchestration/triggers/loop_time_trigger.py\", line 14, in start\n    self.run()\n", "  File \"/usr/local/lib/python3.10/site-packages/mage_ai/orchestration/triggers/time_trigger.py\", line 11, in run\n    schedule_all()\n", "  File \"/usr/local/lib/python3.10/site-packages/mage_ai/orchestration/pipeline_scheduler_original.py\", line 1552, in schedule_all\n    PipelineScheduler(r).start()\n", "  File \"/usr/local/lib/python3.10/site-packages/mage_ai/orchestration/db/__init__.py\", line 149, in func_with_rollback\n    return func(*args, **kwargs)\n", "  File \"/usr/local/lib/python3.10/site-packages/mage_ai/orchestration/pipeline_scheduler_original.py\", line 182, in start\n    self.schedule()\n", "  File \"/usr/local/lib/python3.10/site-packages/mage_ai/orchestration/db/__init__.py\", line 149, in func_with_rollback\n    return func(*args, **kwargs)\n", "  File \"/usr/local/lib/python3.10/site-packages/mage_ai/orchestration/pipeline_scheduler_original.py\", line 319, in schedule\n    self.__schedule_blocks(block_runs)\n", "  File \"/usr/local/lib/python3.10/site-packages/mage_ai/orchestration/pipeline_scheduler_original.py\", line 581, in __schedule_blocks\n    job_manager.add_job(\n", "  File \"/usr/local/lib/python3.10/site-packages/mage_ai/orchestration/job_manager.py\", line 27, in add_job\n    self.queue.enqueue(job_id, target, *args, **kwargs)\n", "  File \"/usr/local/lib/python3.10/site-packages/mage_ai/orchestration/queue/process_queue.py\", line 107, in enqueue\n    self.start_worker_pool()\n", "  File \"/usr/local/lib/python3.10/site-packages/mage_ai/orchestration/queue/process_queue.py\", line 173, in start_worker_pool\n    self.worker_pool_proc.start()\n", "  File \"/usr/local/lib/python3.10/multiprocessing/process.py\", line 121, in start\n    self._popen = self._Popen(self)\n", "  File \"/usr/local/lib/python3.10/multiprocessing/context.py\", line 224, in _Popen\n    return _default_context.get_context().Process._Popen(process_obj)\n", "  File \"/usr/local/lib/python3.10/multiprocessing/context.py\", line 281, in _Popen\n    return Popen(process_obj)\n", "  File \"/usr/local/lib/python3.10/multiprocessing/popen_fork.py\", line 19, in __init__\n    self._launch(process_obj)\n", "  File \"/usr/local/lib/python3.10/multiprocessing/popen_fork.py\", line 71, in _launch\n    code = process_obj._bootstrap(parent_sentinel=child_r)\n", "  File \"/usr/local/lib/python3.10/multiprocessing/process.py\", line 314, in _bootstrap\n    self.run()\n", "  File \"/usr/local/lib/python3.10/multiprocessing/process.py\", line 108, in run\n    self._target(*self._args, **self._kwargs)\n", "  File \"/usr/local/lib/python3.10/site-packages/mage_ai/orchestration/queue/process_queue.py\", line 275, in poll_job_and_execute\n    worker.start()\n", "  File \"/usr/local/lib/python3.10/multiprocessing/process.py\", line 121, in start\n    self._popen = self._Popen(self)\n", "  File \"/usr/local/lib/python3.10/multiprocessing/context.py\", line 224, in _Popen\n    return _default_context.get_context().Process._Popen(process_obj)\n", "  File \"/usr/local/lib/python3.10/multiprocessing/context.py\", line 281, in _Popen\n    return Popen(process_obj)\n", "  File \"/usr/local/lib/python3.10/multiprocessing/popen_fork.py\", line 19, in __init__\n    self._launch(process_obj)\n", "  File \"/usr/local/lib/python3.10/multiprocessing/popen_fork.py\", line 71, in _launch\n    code = process_obj._bootstrap(parent_sentinel=child_r)\n", "  File \"/usr/local/lib/python3.10/multiprocessing/process.py\", line 314, in _bootstrap\n    self.run()\n", "  File \"/usr/local/lib/python3.10/site-packages/newrelic/api/background_task.py\", line 117, in wrapper\n    return wrapped(*args, **kwargs)\n", "  File \"/usr/local/lib/python3.10/site-packages/mage_ai/orchestration/queue/process_queue.py\", line 240, in run\n    start_session_and_run(args[1], *args[2], **args[3])\n", "  File \"/usr/local/lib/python3.10/site-packages/mage_ai/orchestration/db/process.py\", line 15, in start_session_and_run\n    results = target(*args)\n", "  File \"/usr/local/lib/python3.10/site-packages/mage_ai/orchestration/pipeline_scheduler_original.py\", line 1105, in run_block\n    return ExecutorFactory.get_block_executor(\n", "  File \"/usr/local/lib/python3.10/site-packages/mage_ai/data_preparation/executors/block_executor.py\", line 639, in execute\n    on_failure(\n", "  File \"/usr/local/lib/python3.10/site-packages/mage_ai/orchestration/db/__init__.py\", line 149, in func_with_rollback\n    return func(*args, **kwargs)\n", "  File \"/usr/local/lib/python3.10/site-packages/mage_ai/orchestration/pipeline_scheduler_original.py\", line 415, in on_block_failure\n    self.logger.exception(\n", "  File \"/usr/local/lib/python3.10/site-packages/mage_ai/data_preparation/logging/logger.py\", line 30, in exception\n    self.__send_message('exception', message, **kwargs)\n", "  File \"/usr/local/lib/python3.10/site-packages/mage_ai/data_preparation/logging/logger.py\", line 59, in __send_message\n    data['error_stack'] = traceback.format_stack(),\n"]], "error_stacktrace": ["Pipeline execution failed at stage extract when processing package 1713111985.9029875 with exception:\n\n<class 'dlt.extract.exceptions.ResourceExtractionError'>\nIn processing pipe src_daily_standings: extraction of resource src_daily_standings in generator load_daily_standings caused an exception: 'standingsdate'"]}
Traceback (most recent call last):
  File "/usr/local/lib/python3.10/site-packages/pandas/core/indexes/base.py", line 3802, in get_loc
    return self._engine.get_loc(casted_key)
  File "index.pyx", line 153, in pandas._libs.index.IndexEngine.get_loc
  File "index.pyx", line 182, in pandas._libs.index.IndexEngine.get_loc
  File "pandas/_libs/hashtable_class_helper.pxi", line 7081, in pandas._libs.hashtable.PyObjectHashTable.get_item
  File "pandas/_libs/hashtable_class_helper.pxi", line 7089, in pandas._libs.hashtable.PyObjectHashTable.get_item
KeyError: 'standingsdate'

The above exception was the direct cause of the following exception:

Traceback (most recent call last):
  File "/home/src/./mage_nba_watchability_index/utils/dlt_resources/dlt_nba.py", line 124, in load_daily_standings
    ec['standingsdate'] = pd.to_datetime(ec['standingsdate'], format="%d/%m/%Y")
  File "/usr/local/lib/python3.10/site-packages/pandas/core/frame.py", line 4090, in __getitem__
    indexer = self.columns.get_loc(key)
  File "/usr/local/lib/python3.10/site-packages/pandas/core/indexes/base.py", line 3809, in get_loc
    raise KeyError(key) from err
KeyError: 'standingsdate'

During handling of the above exception, another exception occurred:

Traceback (most recent call last):
  File "/usr/local/lib/python3.10/site-packages/pandas/core/indexes/base.py", line 3802, in get_loc
    return self._engine.get_loc(casted_key)
  File "index.pyx", line 153, in pandas._libs.index.IndexEngine.get_loc
  File "index.pyx", line 182, in pandas._libs.index.IndexEngine.get_loc
  File "pandas/_libs/hashtable_class_helper.pxi", line 7081, in pandas._libs.hashtable.PyObjectHashTable.get_item
  File "pandas/_libs/hashtable_class_helper.pxi", line 7089, in pandas._libs.hashtable.PyObjectHashTable.get_item
KeyError: 'standingsdate'

The above exception was the direct cause of the following exception:

Traceback (most recent call last):
  File "/usr/local/lib/python3.10/site-packages/dlt/extract/pipe.py", line 837, in _get_source_item
    if (item := next(gen)) is not None:
  File "/home/src/./mage_nba_watchability_index/utils/dlt_resources/dlt_nba.py", line 148, in load_daily_standings
    ec['standingsdate'] = pd.to_datetime(ec['standingsdate'], format="%d/%m/%Y")
  File "/usr/local/lib/python3.10/site-packages/pandas/core/frame.py", line 4090, in __getitem__
    indexer = self.columns.get_loc(key)
  File "/usr/local/lib/python3.10/site-packages/pandas/core/indexes/base.py", line 3809, in get_loc
    raise KeyError(key) from err
KeyError: 'standingsdate'

The above exception was the direct cause of the following exception:

Traceback (most recent call last):
  File "/usr/local/lib/python3.10/site-packages/dlt/pipeline/pipeline.py", line 391, in extract
    self._extract_source(extract_step, source, max_parallel_items, workers)
  File "/usr/local/lib/python3.10/site-packages/dlt/pipeline/pipeline.py", line 1028, in _extract_source
    load_id = extract.extract(source, max_parallel_items, workers)
  File "/usr/local/lib/python3.10/site-packages/dlt/extract/extract.py", line 341, in extract
    self._extract_single_source(
  File "/usr/local/lib/python3.10/site-packages/dlt/extract/extract.py", line 271, in _extract_single_source
    for pipe_item in pipes:
  File "/usr/local/lib/python3.10/site-packages/dlt/extract/pipe.py", line 605, in __next__
    pipe_item = self._get_source_item()
  File "/usr/local/lib/python3.10/site-packages/dlt/extract/pipe.py", line 863, in _get_source_item
    raise ResourceExtractionError(pipe.name, gen, str(ex), "generator") from ex
dlt.extract.exceptions.ResourceExtractionError: In processing pipe src_daily_standings: extraction of resource src_daily_standings in generator load_daily_standings caused an exception: 'standingsdate'

The above exception was the direct cause of the following exception:

Traceback (most recent call last):
  File "/usr/local/lib/python3.10/site-packages/mage_ai/data_preparation/executors/block_executor.py", line 612, in execute
    result = __execute_with_retry()
  File "/usr/local/lib/python3.10/site-packages/mage_ai/shared/retry.py", line 54, in retry_func
    raise e
  File "/usr/local/lib/python3.10/site-packages/mage_ai/shared/retry.py", line 38, in retry_func
    return func(*args, **kwargs)
  File "/usr/local/lib/python3.10/site-packages/mage_ai/data_preparation/executors/block_executor.py", line 587, in __execute_with_retry
    return self._execute(
  File "/usr/local/lib/python3.10/site-packages/mage_ai/data_preparation/executors/block_executor.py", line 1075, in _execute
    result = self.block.execute_sync(
  File "/usr/local/lib/python3.10/site-packages/mage_ai/data_preparation/models/block/__init__.py", line 1312, in execute_sync
    raise err
  File "/usr/local/lib/python3.10/site-packages/mage_ai/data_preparation/models/block/__init__.py", line 1221, in execute_sync
    output = self.execute_block(
  File "/usr/local/lib/python3.10/site-packages/mage_ai/data_preparation/models/block/__init__.py", line 1527, in execute_block
    outputs = self._execute_block(
  File "/usr/local/lib/python3.10/site-packages/mage_ai/data_preparation/models/block/__init__.py", line 1683, in _execute_block
    outputs = self.execute_block_function(
  File "/usr/local/lib/python3.10/site-packages/mage_ai/data_preparation/models/block/__init__.py", line 1722, in execute_block_function
    output = block_function_updated(*input_vars, **global_vars)
  File "<string>", line 58, in load_data
  File "/usr/local/lib/python3.10/site-packages/dlt/pipeline/pipeline.py", line 193, in _wrap
    step_info = f(self, *args, **kwargs)
  File "/usr/local/lib/python3.10/site-packages/dlt/pipeline/pipeline.py", line 238, in _wrap
    return f(self, *args, **kwargs)
  File "/usr/local/lib/python3.10/site-packages/dlt/pipeline/pipeline.py", line 619, in run
    self.extract(
  File "/usr/local/lib/python3.10/site-packages/dlt/pipeline/pipeline.py", line 193, in _wrap
    step_info = f(self, *args, **kwargs)
  File "/usr/local/lib/python3.10/site-packages/dlt/pipeline/pipeline.py", line 164, in _wrap
    rv = f(self, *args, **kwargs)
  File "/usr/local/lib/python3.10/site-packages/dlt/pipeline/pipeline.py", line 151, in _wrap
    return f(self, *args, **kwargs)
  File "/usr/local/lib/python3.10/site-packages/dlt/pipeline/pipeline.py", line 238, in _wrap
    return f(self, *args, **kwargs)
  File "/usr/local/lib/python3.10/site-packages/dlt/pipeline/pipeline.py", line 403, in extract
    raise PipelineStepFailed(
dlt.pipeline.exceptions.PipelineStepFailed: Pipeline execution failed at stage extract when processing package 1713111985.9029875 with exception:

<class 'dlt.extract.exceptions.ResourceExtractionError'>
In processing pipe src_daily_standings: extraction of resource src_daily_standings in generator load_daily_standings caused an exception: 'standingsdate'
2024-04-14T16:26:36 {"cpu": 0.2900390625, "cpu_total": 8, "cpu_usage": 0.0362548828125, "memory": 3411.0, "memory_total": 9922.0, "memory_usage": 0.3437814956661963, "pipeline_run_id": 3, "pipeline_schedule_id": 3, "pipeline_uuid": "seed_bq", "hostname": "78c121f5c730", "level": "INFO", "message": "Pipeline seed_bq for run 3 in schedule 3 is alive.", "timestamp": 1713111996.180777, "uuid": "e9cc225a1cc64b5baeec7db6e92396bc"}
