2024-04-14T18:23:12 {"block_run_id": 13, "block_uuid": "api_to_bigquery", "pipeline_run_id": 6, "pipeline_schedule_id": 6, "pipeline_uuid": "seed_bq", "hostname": "ee16a9cfd313", "block_type": "data_loader", "level": "INFO", "message": "Start executing block with BlockExecutor.", "timestamp": 1713118992.414293, "uuid": "d0208959e56e40229d6168ac5a673fba"}
2024-04-14T18:23:37 {"block_run_id": 13, "block_uuid": "api_to_bigquery", "pipeline_run_id": 6, "pipeline_schedule_id": 6, "pipeline_uuid": "seed_bq", "hostname": "ee16a9cfd313", "block_type": "data_loader", "level": "INFO", "message": "Getting standings for 172 days from today", "timestamp": 1713119017.480907, "uuid": "309ae0508f2940a382d595b598f7e25e"}
2024-04-14T18:23:37 {"block_run_id": 13, "block_uuid": "api_to_bigquery", "pipeline_run_id": 6, "pipeline_schedule_id": 6, "pipeline_uuid": "seed_bq", "hostname": "ee16a9cfd313", "block_type": "data_loader", "level": "INFO", "message": "Getting standings for 171 days from today", "timestamp": 1713119017.933016, "uuid": "99ff8849998a41e78476683b7f6d7a00"}
2024-04-14T18:23:38 {"block_run_id": 13, "block_uuid": "api_to_bigquery", "pipeline_run_id": 6, "pipeline_schedule_id": 6, "pipeline_uuid": "seed_bq", "hostname": "ee16a9cfd313", "block_type": "data_loader", "level": "INFO", "message": "Getting standings for 170 days from today", "timestamp": 1713119018.410198, "uuid": "0b38f484614044c7abef77f7e9dd8595"}
2024-04-14T18:23:38 {"block_run_id": 13, "block_uuid": "api_to_bigquery", "pipeline_run_id": 6, "pipeline_schedule_id": 6, "pipeline_uuid": "seed_bq", "hostname": "ee16a9cfd313", "block_type": "data_loader", "level": "INFO", "message": "Getting standings for 169 days from today", "timestamp": 1713119018.772511, "uuid": "99ec33db44d84b3fbd0a02a615abb94b"}
2024-04-14T18:23:39 {"block_run_id": 13, "block_uuid": "api_to_bigquery", "pipeline_run_id": 6, "pipeline_schedule_id": 6, "pipeline_uuid": "seed_bq", "hostname": "ee16a9cfd313", "block_type": "data_loader", "level": "INFO", "message": "Getting standings for 168 days from today", "timestamp": 1713119019.29156, "uuid": "897d0c1326224bbda773f0aaaa3d96a9"}
2024-04-14T18:23:39 {"block_run_id": 13, "block_uuid": "api_to_bigquery", "pipeline_run_id": 6, "pipeline_schedule_id": 6, "pipeline_uuid": "seed_bq", "hostname": "ee16a9cfd313", "block_type": "data_loader", "level": "INFO", "message": "Getting standings for 167 days from today", "timestamp": 1713119019.684599, "uuid": "02f646ca5ff8456b946c6d5695272af9"}
2024-04-14T18:23:40 {"block_run_id": 13, "block_uuid": "api_to_bigquery", "pipeline_run_id": 6, "pipeline_schedule_id": 6, "pipeline_uuid": "seed_bq", "hostname": "ee16a9cfd313", "block_type": "data_loader", "level": "INFO", "message": "Getting standings for 166 days from today", "timestamp": 1713119020.129001, "uuid": "7748728f9d0c4ff18ec737a9dffa98d1"}
2024-04-14T18:23:40 {"block_run_id": 13, "block_uuid": "api_to_bigquery", "pipeline_run_id": 6, "pipeline_schedule_id": 6, "pipeline_uuid": "seed_bq", "hostname": "ee16a9cfd313", "block_type": "data_loader", "level": "INFO", "message": "Getting standings for 165 days from today", "timestamp": 1713119020.592627, "uuid": "eaaa51ef6cfd41f0a82051f22cdd282b"}
2024-04-14T18:23:41 {"block_run_id": 13, "block_uuid": "api_to_bigquery", "pipeline_run_id": 6, "pipeline_schedule_id": 6, "pipeline_uuid": "seed_bq", "hostname": "ee16a9cfd313", "block_type": "data_loader", "level": "INFO", "message": "Getting standings for 164 days from today", "timestamp": 1713119021.195189, "uuid": "d0c921a2b93e4de582cb181d17906df1"}
2024-04-14T18:23:41 {"block_run_id": 13, "block_uuid": "api_to_bigquery", "pipeline_run_id": 6, "pipeline_schedule_id": 6, "pipeline_uuid": "seed_bq", "hostname": "ee16a9cfd313", "block_type": "data_loader", "level": "INFO", "message": "Getting standings for 163 days from today", "timestamp": 1713119021.653837, "uuid": "d9c4eed223ea426e8a4f32ab4ae5bd74"}
2024-04-14T18:23:42 {"block_run_id": 13, "block_uuid": "api_to_bigquery", "pipeline_run_id": 6, "pipeline_schedule_id": 6, "pipeline_uuid": "seed_bq", "hostname": "ee16a9cfd313", "block_type": "data_loader", "level": "INFO", "message": "Getting standings for 162 days from today", "timestamp": 1713119022.131384, "uuid": "64f4a4743dd849008fcc134480f8c17e"}
2024-04-14T18:23:42 {"block_run_id": 13, "block_uuid": "api_to_bigquery", "pipeline_run_id": 6, "pipeline_schedule_id": 6, "pipeline_uuid": "seed_bq", "hostname": "ee16a9cfd313", "block_type": "data_loader", "level": "INFO", "message": "Getting standings for 161 days from today", "timestamp": 1713119022.616147, "uuid": "fff262ce146c49f58ad348c7fcf302a6"}
2024-04-14T18:23:43 {"block_run_id": 13, "block_uuid": "api_to_bigquery", "pipeline_run_id": 6, "pipeline_schedule_id": 6, "pipeline_uuid": "seed_bq", "hostname": "ee16a9cfd313", "block_type": "data_loader", "level": "INFO", "message": "Getting standings for 160 days from today", "timestamp": 1713119023.008239, "uuid": "5dae34dcf1a945fc966571c2f6d404b0"}
2024-04-14T18:23:43 {"block_run_id": 13, "block_uuid": "api_to_bigquery", "pipeline_run_id": 6, "pipeline_schedule_id": 6, "pipeline_uuid": "seed_bq", "hostname": "ee16a9cfd313", "block_type": "data_loader", "level": "INFO", "message": "Getting standings for 159 days from today", "timestamp": 1713119023.390005, "uuid": "0fff85740a88445eb02313f709cd0c44"}
2024-04-14T18:23:43 {"block_run_id": 13, "block_uuid": "api_to_bigquery", "pipeline_run_id": 6, "pipeline_schedule_id": 6, "pipeline_uuid": "seed_bq", "hostname": "ee16a9cfd313", "block_type": "data_loader", "level": "INFO", "message": "Getting standings for 158 days from today", "timestamp": 1713119023.781921, "uuid": "a356c0553b8e4436ac21590d629dc94f"}
2024-04-14T18:23:44 {"block_run_id": 13, "block_uuid": "api_to_bigquery", "pipeline_run_id": 6, "pipeline_schedule_id": 6, "pipeline_uuid": "seed_bq", "hostname": "ee16a9cfd313", "block_type": "data_loader", "level": "INFO", "message": "Getting standings for 157 days from today", "timestamp": 1713119024.174148, "uuid": "9206e565887c494eb5054082c9c90008"}
2024-04-14T18:23:44 {"block_run_id": 13, "block_uuid": "api_to_bigquery", "pipeline_run_id": 6, "pipeline_schedule_id": 6, "pipeline_uuid": "seed_bq", "hostname": "ee16a9cfd313", "block_type": "data_loader", "level": "INFO", "message": "Getting standings for 156 days from today", "timestamp": 1713119024.629888, "uuid": "0b1c5ae5cac74cfa9cbb0ea0786f624a"}
2024-04-14T18:23:45 {"block_run_id": 13, "block_uuid": "api_to_bigquery", "pipeline_run_id": 6, "pipeline_schedule_id": 6, "pipeline_uuid": "seed_bq", "hostname": "ee16a9cfd313", "block_type": "data_loader", "level": "INFO", "message": "Getting standings for 155 days from today", "timestamp": 1713119025.100835, "uuid": "2e9bee7952be47ceb423cc77667b40df"}
2024-04-14T18:23:45 {"block_run_id": 13, "block_uuid": "api_to_bigquery", "pipeline_run_id": 6, "pipeline_schedule_id": 6, "pipeline_uuid": "seed_bq", "hostname": "ee16a9cfd313", "block_type": "data_loader", "level": "INFO", "message": "Getting standings for 154 days from today", "timestamp": 1713119025.537617, "uuid": "d4333903cc364e74a00999b012229db0"}
2024-04-14T18:23:45 {"block_run_id": 13, "block_uuid": "api_to_bigquery", "pipeline_run_id": 6, "pipeline_schedule_id": 6, "pipeline_uuid": "seed_bq", "hostname": "ee16a9cfd313", "block_type": "data_loader", "level": "INFO", "message": "Getting standings for 153 days from today", "timestamp": 1713119025.889847, "uuid": "856bad5f88cd4b4aac828889ead2c920"}
2024-04-14T18:23:46 {"block_run_id": 13, "block_uuid": "api_to_bigquery", "pipeline_run_id": 6, "pipeline_schedule_id": 6, "pipeline_uuid": "seed_bq", "hostname": "ee16a9cfd313", "block_type": "data_loader", "level": "INFO", "message": "Getting standings for 152 days from today", "timestamp": 1713119026.363491, "uuid": "a9aaafd1f8634ea5b0e2b26ff87641b3"}
2024-04-14T18:23:46 {"block_run_id": 13, "block_uuid": "api_to_bigquery", "pipeline_run_id": 6, "pipeline_schedule_id": 6, "pipeline_uuid": "seed_bq", "hostname": "ee16a9cfd313", "block_type": "data_loader", "level": "INFO", "message": "Getting standings for 151 days from today", "timestamp": 1713119026.865911, "uuid": "6c6cb9fcde5b4515b9c0639276f5f1b3"}
2024-04-14T18:23:47 {"block_run_id": 13, "block_uuid": "api_to_bigquery", "pipeline_run_id": 6, "pipeline_schedule_id": 6, "pipeline_uuid": "seed_bq", "hostname": "ee16a9cfd313", "block_type": "data_loader", "level": "INFO", "message": "Getting standings for 150 days from today", "timestamp": 1713119027.329062, "uuid": "37159705491f43fcba6cd6eb5f0607e1"}
2024-04-14T18:23:47 {"block_run_id": 13, "block_uuid": "api_to_bigquery", "pipeline_run_id": 6, "pipeline_schedule_id": 6, "pipeline_uuid": "seed_bq", "hostname": "ee16a9cfd313", "block_type": "data_loader", "level": "INFO", "message": "Getting standings for 149 days from today", "timestamp": 1713119027.78571, "uuid": "5739dc50cf31402f8e147a41d4993d07"}
2024-04-14T18:23:48 {"block_run_id": 13, "block_uuid": "api_to_bigquery", "pipeline_run_id": 6, "pipeline_schedule_id": 6, "pipeline_uuid": "seed_bq", "hostname": "ee16a9cfd313", "block_type": "data_loader", "level": "INFO", "message": "Getting standings for 148 days from today", "timestamp": 1713119028.265523, "uuid": "9985eb08b7f24ccf87247da724576e76"}
2024-04-14T18:23:48 {"block_run_id": 13, "block_uuid": "api_to_bigquery", "pipeline_run_id": 6, "pipeline_schedule_id": 6, "pipeline_uuid": "seed_bq", "hostname": "ee16a9cfd313", "block_type": "data_loader", "level": "INFO", "message": "Getting standings for 147 days from today", "timestamp": 1713119028.694303, "uuid": "b4c4fa3da38e46ce9bf6efc88fc8a7c1"}
2024-04-14T18:23:49 {"block_run_id": 13, "block_uuid": "api_to_bigquery", "pipeline_run_id": 6, "pipeline_schedule_id": 6, "pipeline_uuid": "seed_bq", "hostname": "ee16a9cfd313", "block_type": "data_loader", "level": "INFO", "message": "Getting standings for 146 days from today", "timestamp": 1713119029.096109, "uuid": "f3ef07bb062d46e9ac66cea21ca7c905"}
2024-04-14T18:23:49 {"block_run_id": 13, "block_uuid": "api_to_bigquery", "pipeline_run_id": 6, "pipeline_schedule_id": 6, "pipeline_uuid": "seed_bq", "hostname": "ee16a9cfd313", "block_type": "data_loader", "level": "INFO", "message": "Getting standings for 145 days from today", "timestamp": 1713119029.518371, "uuid": "83a49effbed94989ac5771c396b19c73"}
2024-04-14T18:23:49 {"block_run_id": 13, "block_uuid": "api_to_bigquery", "pipeline_run_id": 6, "pipeline_schedule_id": 6, "pipeline_uuid": "seed_bq", "hostname": "ee16a9cfd313", "block_type": "data_loader", "level": "INFO", "message": "Getting standings for 144 days from today", "timestamp": 1713119029.898517, "uuid": "4fc9ac4e6ed2467ca2a7b622ecba29e6"}
2024-04-14T18:23:50 {"block_run_id": 13, "block_uuid": "api_to_bigquery", "pipeline_run_id": 6, "pipeline_schedule_id": 6, "pipeline_uuid": "seed_bq", "hostname": "ee16a9cfd313", "block_type": "data_loader", "level": "INFO", "message": "Getting standings for 143 days from today", "timestamp": 1713119030.43716, "uuid": "4c2f7c15bae347ca8c91856caaa52596"}
2024-04-14T18:23:50 {"block_run_id": 13, "block_uuid": "api_to_bigquery", "pipeline_run_id": 6, "pipeline_schedule_id": 6, "pipeline_uuid": "seed_bq", "hostname": "ee16a9cfd313", "block_type": "data_loader", "level": "INFO", "message": "Getting standings for 142 days from today", "timestamp": 1713119030.88614, "uuid": "3f50def3d2e14ee99f9da581248beee5"}
2024-04-14T18:23:51 {"block_run_id": 13, "block_uuid": "api_to_bigquery", "pipeline_run_id": 6, "pipeline_schedule_id": 6, "pipeline_uuid": "seed_bq", "hostname": "ee16a9cfd313", "block_type": "data_loader", "level": "INFO", "message": "Getting standings for 141 days from today", "timestamp": 1713119031.296989, "uuid": "c0ff87259f1d4eb893c350d1dddbb026"}
2024-04-14T18:23:51 {"block_run_id": 13, "block_uuid": "api_to_bigquery", "pipeline_run_id": 6, "pipeline_schedule_id": 6, "pipeline_uuid": "seed_bq", "hostname": "ee16a9cfd313", "block_type": "data_loader", "level": "INFO", "message": "Getting standings for 140 days from today", "timestamp": 1713119031.714924, "uuid": "5539a42c5ef24990b25d1d38ad8708b7"}
2024-04-14T18:23:52 {"block_run_id": 13, "block_uuid": "api_to_bigquery", "pipeline_run_id": 6, "pipeline_schedule_id": 6, "pipeline_uuid": "seed_bq", "hostname": "ee16a9cfd313", "block_type": "data_loader", "level": "INFO", "message": "Getting standings for 139 days from today", "timestamp": 1713119032.22995, "uuid": "4d7851ca1b834b5ca5103296ee6c0b53"}
2024-04-14T18:23:52 {"block_run_id": 13, "block_uuid": "api_to_bigquery", "pipeline_run_id": 6, "pipeline_schedule_id": 6, "pipeline_uuid": "seed_bq", "hostname": "ee16a9cfd313", "block_type": "data_loader", "level": "INFO", "message": "Getting standings for 138 days from today", "timestamp": 1713119032.651419, "uuid": "bfec9f26a6624c5bbce66739244fdea5"}
2024-04-14T18:23:53 {"block_run_id": 13, "block_uuid": "api_to_bigquery", "pipeline_run_id": 6, "pipeline_schedule_id": 6, "pipeline_uuid": "seed_bq", "hostname": "ee16a9cfd313", "block_type": "data_loader", "level": "INFO", "message": "Getting standings for 137 days from today", "timestamp": 1713119033.134011, "uuid": "106bc6aa57e44e518cd88e1fd28f4ba6"}
2024-04-14T18:23:53 {"block_run_id": 13, "block_uuid": "api_to_bigquery", "pipeline_run_id": 6, "pipeline_schedule_id": 6, "pipeline_uuid": "seed_bq", "hostname": "ee16a9cfd313", "block_type": "data_loader", "level": "INFO", "message": "Getting standings for 136 days from today", "timestamp": 1713119033.558386, "uuid": "0a8d9fa442774708ad30b5f43c94c591"}
2024-04-14T18:23:54 {"block_run_id": 13, "block_uuid": "api_to_bigquery", "pipeline_run_id": 6, "pipeline_schedule_id": 6, "pipeline_uuid": "seed_bq", "hostname": "ee16a9cfd313", "block_type": "data_loader", "level": "INFO", "message": "Getting standings for 135 days from today", "timestamp": 1713119034.1729, "uuid": "827135340cc44528877e8f4f07fcaaba"}
2024-04-14T18:23:55 {"block_run_id": 13, "block_uuid": "api_to_bigquery", "pipeline_run_id": 6, "pipeline_schedule_id": 6, "pipeline_uuid": "seed_bq", "hostname": "ee16a9cfd313", "block_type": "data_loader", "level": "INFO", "message": "Getting standings for 134 days from today", "timestamp": 1713119035.024007, "uuid": "6c1edd71d57d4dba95c6eab8ca422d98"}
2024-04-14T18:23:55 {"block_run_id": 13, "block_uuid": "api_to_bigquery", "pipeline_run_id": 6, "pipeline_schedule_id": 6, "pipeline_uuid": "seed_bq", "hostname": "ee16a9cfd313", "block_type": "data_loader", "level": "INFO", "message": "Getting standings for 133 days from today", "timestamp": 1713119035.49723, "uuid": "9aefd2147f5145ad826039c301b00a3d"}
2024-04-14T18:23:55 {"block_run_id": 13, "block_uuid": "api_to_bigquery", "pipeline_run_id": 6, "pipeline_schedule_id": 6, "pipeline_uuid": "seed_bq", "hostname": "ee16a9cfd313", "block_type": "data_loader", "level": "INFO", "message": "Getting standings for 132 days from today", "timestamp": 1713119035.953805, "uuid": "87aec47f0a0e4c7f8a344c623853d4c0"}
2024-04-14T18:23:56 {"block_run_id": 13, "block_uuid": "api_to_bigquery", "pipeline_run_id": 6, "pipeline_schedule_id": 6, "pipeline_uuid": "seed_bq", "hostname": "ee16a9cfd313", "block_type": "data_loader", "level": "INFO", "message": "Getting standings for 131 days from today", "timestamp": 1713119036.442011, "uuid": "9094cfc2b9c44ce89f9a00caaba1dda1"}
2024-04-14T18:23:56 {"block_run_id": 13, "block_uuid": "api_to_bigquery", "pipeline_run_id": 6, "pipeline_schedule_id": 6, "pipeline_uuid": "seed_bq", "hostname": "ee16a9cfd313", "block_type": "data_loader", "level": "INFO", "message": "Getting standings for 130 days from today", "timestamp": 1713119036.964596, "uuid": "5b61c06951bd48a9a57d59ac20d730bf"}
2024-04-14T18:23:57 {"block_run_id": 13, "block_uuid": "api_to_bigquery", "pipeline_run_id": 6, "pipeline_schedule_id": 6, "pipeline_uuid": "seed_bq", "hostname": "ee16a9cfd313", "block_type": "data_loader", "level": "INFO", "message": "Getting standings for 129 days from today", "timestamp": 1713119037.361424, "uuid": "89393957efb049a6b8fcd1a06b3b3477"}
2024-04-14T18:23:58 {"block_run_id": 13, "block_uuid": "api_to_bigquery", "pipeline_run_id": 6, "pipeline_schedule_id": 6, "pipeline_uuid": "seed_bq", "hostname": "ee16a9cfd313", "block_type": "data_loader", "level": "INFO", "message": "Getting standings for 128 days from today", "timestamp": 1713119038.055942, "uuid": "e79baa61990f499ca2f6ede196dba572"}
2024-04-14T18:23:58 {"block_run_id": 13, "block_uuid": "api_to_bigquery", "pipeline_run_id": 6, "pipeline_schedule_id": 6, "pipeline_uuid": "seed_bq", "hostname": "ee16a9cfd313", "block_type": "data_loader", "level": "INFO", "message": "Getting standings for 127 days from today", "timestamp": 1713119038.476258, "uuid": "28c7f1e419a24e2b861acd3e2550afa9"}
2024-04-14T18:23:58 {"block_run_id": 13, "block_uuid": "api_to_bigquery", "pipeline_run_id": 6, "pipeline_schedule_id": 6, "pipeline_uuid": "seed_bq", "hostname": "ee16a9cfd313", "block_type": "data_loader", "level": "INFO", "message": "Getting standings for 126 days from today", "timestamp": 1713119038.882549, "uuid": "896dad48abdd4d589edb04921538f0a8"}
2024-04-14T18:23:59 {"block_run_id": 13, "block_uuid": "api_to_bigquery", "pipeline_run_id": 6, "pipeline_schedule_id": 6, "pipeline_uuid": "seed_bq", "hostname": "ee16a9cfd313", "block_type": "data_loader", "level": "INFO", "message": "Getting standings for 125 days from today", "timestamp": 1713119039.367469, "uuid": "4234f574d40047449af9b249bdd9832e"}
2024-04-14T18:23:59 {"block_run_id": 13, "block_uuid": "api_to_bigquery", "pipeline_run_id": 6, "pipeline_schedule_id": 6, "pipeline_uuid": "seed_bq", "hostname": "ee16a9cfd313", "block_type": "data_loader", "level": "INFO", "message": "Getting standings for 124 days from today", "timestamp": 1713119039.824074, "uuid": "549ef4f92f2e49e6b416a1656afc6856"}
2024-04-14T18:24:00 {"block_run_id": 13, "block_uuid": "api_to_bigquery", "pipeline_run_id": 6, "pipeline_schedule_id": 6, "pipeline_uuid": "seed_bq", "hostname": "ee16a9cfd313", "block_type": "data_loader", "level": "INFO", "message": "Getting standings for 123 days from today", "timestamp": 1713119040.39194, "uuid": "b4d9ec3f7fbb446ab4d0ccee24136d3b"}
2024-04-14T18:24:01 {"block_run_id": 13, "block_uuid": "api_to_bigquery", "pipeline_run_id": 6, "pipeline_schedule_id": 6, "pipeline_uuid": "seed_bq", "hostname": "ee16a9cfd313", "block_type": "data_loader", "level": "INFO", "message": "Getting standings for 122 days from today", "timestamp": 1713119041.160623, "uuid": "ac73812942744e17b322536a05e8b43f"}
2024-04-14T18:24:01 {"block_run_id": 13, "block_uuid": "api_to_bigquery", "pipeline_run_id": 6, "pipeline_schedule_id": 6, "pipeline_uuid": "seed_bq", "hostname": "ee16a9cfd313", "block_type": "data_loader", "level": "INFO", "message": "Getting standings for 121 days from today", "timestamp": 1713119041.692667, "uuid": "a100da512e8b4b678fb5a23bef8c7ea8"}
2024-04-14T18:24:02 {"block_run_id": 13, "block_uuid": "api_to_bigquery", "pipeline_run_id": 6, "pipeline_schedule_id": 6, "pipeline_uuid": "seed_bq", "hostname": "ee16a9cfd313", "block_type": "data_loader", "level": "INFO", "message": "Getting standings for 120 days from today", "timestamp": 1713119042.178761, "uuid": "74699be0ad164dffa648aef8e9d7a2b8"}
2024-04-14T18:24:02 {"block_run_id": 13, "block_uuid": "api_to_bigquery", "pipeline_run_id": 6, "pipeline_schedule_id": 6, "pipeline_uuid": "seed_bq", "hostname": "ee16a9cfd313", "block_type": "data_loader", "level": "INFO", "message": "Getting standings for 119 days from today", "timestamp": 1713119042.670522, "uuid": "f5279637fc3445e6b1c17b292dd01c7c"}
2024-04-14T18:24:03 {"block_run_id": 13, "block_uuid": "api_to_bigquery", "pipeline_run_id": 6, "pipeline_schedule_id": 6, "pipeline_uuid": "seed_bq", "hostname": "ee16a9cfd313", "block_type": "data_loader", "level": "INFO", "message": "Getting standings for 118 days from today", "timestamp": 1713119043.190735, "uuid": "8f412d454e6b4c48b039b495b120b212"}
2024-04-14T18:24:03 {"block_run_id": 13, "block_uuid": "api_to_bigquery", "pipeline_run_id": 6, "pipeline_schedule_id": 6, "pipeline_uuid": "seed_bq", "hostname": "ee16a9cfd313", "block_type": "data_loader", "level": "INFO", "message": "Getting standings for 117 days from today", "timestamp": 1713119043.726145, "uuid": "8bbc00e726cb4345af230106753a5104"}
2024-04-14T18:24:04 {"block_run_id": 13, "block_uuid": "api_to_bigquery", "pipeline_run_id": 6, "pipeline_schedule_id": 6, "pipeline_uuid": "seed_bq", "hostname": "ee16a9cfd313", "block_type": "data_loader", "level": "INFO", "message": "Getting standings for 116 days from today", "timestamp": 1713119044.373827, "uuid": "50ad621df43e4e3badfeeb5b5f6d847e"}
2024-04-14T18:24:04 {"block_run_id": 13, "block_uuid": "api_to_bigquery", "pipeline_run_id": 6, "pipeline_schedule_id": 6, "pipeline_uuid": "seed_bq", "hostname": "ee16a9cfd313", "block_type": "data_loader", "level": "INFO", "message": "Getting standings for 115 days from today", "timestamp": 1713119044.732449, "uuid": "7237fbbd3521485ea1a52c808e009240"}
2024-04-14T18:24:05 {"block_run_id": 13, "block_uuid": "api_to_bigquery", "pipeline_run_id": 6, "pipeline_schedule_id": 6, "pipeline_uuid": "seed_bq", "hostname": "ee16a9cfd313", "block_type": "data_loader", "level": "INFO", "message": "Getting standings for 114 days from today", "timestamp": 1713119045.268863, "uuid": "c3731b1376e14f6f8f126b33c98e89af"}
2024-04-14T18:24:05 {"block_run_id": 13, "block_uuid": "api_to_bigquery", "pipeline_run_id": 6, "pipeline_schedule_id": 6, "pipeline_uuid": "seed_bq", "hostname": "ee16a9cfd313", "block_type": "data_loader", "level": "INFO", "message": "Getting standings for 113 days from today", "timestamp": 1713119045.788705, "uuid": "e12e4cbb5461402a8c0879e26f378298"}
2024-04-14T18:24:06 {"block_run_id": 13, "block_uuid": "api_to_bigquery", "pipeline_run_id": 6, "pipeline_schedule_id": 6, "pipeline_uuid": "seed_bq", "hostname": "ee16a9cfd313", "block_type": "data_loader", "level": "INFO", "message": "Getting standings for 112 days from today", "timestamp": 1713119046.188723, "uuid": "272b3fe46f3e475685dfdc863f71b41d"}
2024-04-14T18:24:06 {"block_run_id": 13, "block_uuid": "api_to_bigquery", "pipeline_run_id": 6, "pipeline_schedule_id": 6, "pipeline_uuid": "seed_bq", "hostname": "ee16a9cfd313", "block_type": "data_loader", "level": "INFO", "message": "Getting standings for 111 days from today", "timestamp": 1713119046.544626, "uuid": "6eedb35c7b1b48d6a185d219169d5584"}
2024-04-14T18:24:07 {"block_run_id": 13, "block_uuid": "api_to_bigquery", "pipeline_run_id": 6, "pipeline_schedule_id": 6, "pipeline_uuid": "seed_bq", "hostname": "ee16a9cfd313", "block_type": "data_loader", "level": "INFO", "message": "Getting standings for 110 days from today", "timestamp": 1713119047.053764, "uuid": "4726ec585e4d407581f39a6bbd9b10eb"}
2024-04-14T18:24:07 {"block_run_id": 13, "block_uuid": "api_to_bigquery", "pipeline_run_id": 6, "pipeline_schedule_id": 6, "pipeline_uuid": "seed_bq", "hostname": "ee16a9cfd313", "block_type": "data_loader", "level": "INFO", "message": "Getting standings for 109 days from today", "timestamp": 1713119047.534406, "uuid": "39d87841af6c446c8cef96acafef2c77"}
2024-04-14T18:24:08 {"block_run_id": 13, "block_uuid": "api_to_bigquery", "pipeline_run_id": 6, "pipeline_schedule_id": 6, "pipeline_uuid": "seed_bq", "hostname": "ee16a9cfd313", "block_type": "data_loader", "level": "INFO", "message": "Getting standings for 108 days from today", "timestamp": 1713119048.131552, "uuid": "b916bf86104d4690b1a177a864699fe4"}
2024-04-14T18:24:27 {"block_run_id": 13, "block_uuid": "api_to_bigquery", "pipeline_run_id": 6, "pipeline_schedule_id": 6, "pipeline_uuid": "seed_bq", "hostname": "ee16a9cfd313", "block_type": "data_loader", "level": "INFO", "message": "Retrying getting data for 108 days from today...", "timestamp": 1713119067.850463, "uuid": "2476594c56074f55ad60a5ff06d48bc9"}
2024-04-14T18:24:47 {"block_run_id": 13, "block_uuid": "api_to_bigquery", "pipeline_run_id": 6, "pipeline_schedule_id": 6, "pipeline_uuid": "seed_bq", "hostname": "ee16a9cfd313", "block_type": "data_loader", "level": "WARNING", "message": "Exception thrown when attempting to run <function BlockExecutor.execute.<locals>.__execute_with_retry at 0x7f52f6fc1000>, attempt 1 of 1", "timestamp": 1713119087.347434, "uuid": "b4b71be22826453db99ca52bf8ce763a", "error": ["Traceback (most recent call last):\n  File \"/usr/local/lib/python3.10/site-packages/urllib3/connectionpool.py\", line 715, in urlopen\n    httplib_response = self._make_request(\n  File \"/usr/local/lib/python3.10/site-packages/urllib3/connectionpool.py\", line 467, in _make_request\n    six.raise_from(e, None)\n  File \"<string>\", line 3, in raise_from\n  File \"/usr/local/lib/python3.10/site-packages/urllib3/connectionpool.py\", line 462, in _make_request\n    httplib_response = conn.getresponse()\n  File \"/usr/local/lib/python3.10/http/client.py\", line 1375, in getresponse\n    response.begin()\n  File \"/usr/local/lib/python3.10/http/client.py\", line 318, in begin\n    version, status, reason = self._read_status()\n  File \"/usr/local/lib/python3.10/http/client.py\", line 287, in _read_status\n    raise RemoteDisconnected(\"Remote end closed connection without\"\nhttp.client.RemoteDisconnected: Remote end closed connection without response\n\nDuring handling of the above exception, another exception occurred:\n\nTraceback (most recent call last):\n  File \"/usr/local/lib/python3.10/site-packages/requests/adapters.py\", line 486, in send\n    resp = conn.urlopen(\n  File \"/usr/local/lib/python3.10/site-packages/urllib3/connectionpool.py\", line 799, in urlopen\n    retries = retries.increment(\n  File \"/usr/local/lib/python3.10/site-packages/urllib3/util/retry.py\", line 550, in increment\n    raise six.reraise(type(error), error, _stacktrace)\n  File \"/usr/local/lib/python3.10/site-packages/urllib3/packages/six.py\", line 769, in reraise\n    raise value.with_traceback(tb)\n  File \"/usr/local/lib/python3.10/site-packages/urllib3/connectionpool.py\", line 715, in urlopen\n    httplib_response = self._make_request(\n  File \"/usr/local/lib/python3.10/site-packages/urllib3/connectionpool.py\", line 467, in _make_request\n    six.raise_from(e, None)\n  File \"<string>\", line 3, in raise_from\n  File \"/usr/local/lib/python3.10/site-packages/urllib3/connectionpool.py\", line 462, in _make_request\n    httplib_response = conn.getresponse()\n  File \"/usr/local/lib/python3.10/http/client.py\", line 1375, in getresponse\n    response.begin()\n  File \"/usr/local/lib/python3.10/http/client.py\", line 318, in begin\n    version, status, reason = self._read_status()\n  File \"/usr/local/lib/python3.10/http/client.py\", line 287, in _read_status\n    raise RemoteDisconnected(\"Remote end closed connection without\"\nurllib3.exceptions.ProtocolError: ('Connection aborted.', RemoteDisconnected('Remote end closed connection without response'))\n\nDuring handling of the above exception, another exception occurred:\n\nTraceback (most recent call last):\n  File \"/usr/local/lib/python3.10/site-packages/dlt/extract/pipe.py\", line 837, in _get_source_item\n    if (item := next(gen)) is not None:\n  File \"/home/src/./mage_nba_watchability_index/utils/dlt_resources/dlt_nba.py\", line 151, in load_daily_standings\n    ec = sb.ScoreboardV2(day_offset=-day_offset).east_conf_standings_by_day.get_data_frame()\n  File \"/usr/local/lib/python3.10/site-packages/nba_api/stats/endpoints/scoreboardv2.py\", line 159, in __init__\n    self.get_request()\n  File \"/usr/local/lib/python3.10/site-packages/nba_api/stats/endpoints/scoreboardv2.py\", line 162, in get_request\n    self.nba_response = NBAStatsHTTP().send_api_request(\n  File \"/usr/local/lib/python3.10/site-packages/nba_api/library/http.py\", line 146, in send_api_request\n    response = requests.get(\n  File \"/usr/local/lib/python3.10/site-packages/requests/api.py\", line 73, in get\n    return request(\"get\", url, params=params, **kwargs)\n  File \"/usr/local/lib/python3.10/site-packages/requests/api.py\", line 59, in request\n    return session.request(method=method, url=url, **kwargs)\n  File \"/usr/local/lib/python3.10/site-packages/requests/sessions.py\", line 589, in request\n    resp = self.send(prep, **send_kwargs)\n  File \"/usr/local/lib/python3.10/site-packages/requests/sessions.py\", line 703, in send\n    r = adapter.send(request, **kwargs)\n  File \"/usr/local/lib/python3.10/site-packages/requests/adapters.py\", line 501, in send\n    raise ConnectionError(err, request=request)\nrequests.exceptions.ConnectionError: ('Connection aborted.', RemoteDisconnected('Remote end closed connection without response'))\n\nThe above exception was the direct cause of the following exception:\n\nTraceback (most recent call last):\n  File \"/usr/local/lib/python3.10/site-packages/dlt/pipeline/pipeline.py\", line 391, in extract\n    self._extract_source(extract_step, source, max_parallel_items, workers)\n  File \"/usr/local/lib/python3.10/site-packages/dlt/pipeline/pipeline.py\", line 1028, in _extract_source\n    load_id = extract.extract(source, max_parallel_items, workers)\n  File \"/usr/local/lib/python3.10/site-packages/dlt/extract/extract.py\", line 341, in extract\n    self._extract_single_source(\n  File \"/usr/local/lib/python3.10/site-packages/dlt/extract/extract.py\", line 271, in _extract_single_source\n    for pipe_item in pipes:\n  File \"/usr/local/lib/python3.10/site-packages/dlt/extract/pipe.py\", line 605, in __next__\n    pipe_item = self._get_source_item()\n  File \"/usr/local/lib/python3.10/site-packages/dlt/extract/pipe.py\", line 863, in _get_source_item\n    raise ResourceExtractionError(pipe.name, gen, str(ex), \"generator\") from ex\ndlt.extract.exceptions.ResourceExtractionError: In processing pipe src_daily_standings: extraction of resource src_daily_standings in generator load_daily_standings caused an exception: ('Connection aborted.', RemoteDisconnected('Remote end closed connection without response'))\n\nThe above exception was the direct cause of the following exception:\n\nTraceback (most recent call last):\n  File \"/usr/local/lib/python3.10/site-packages/mage_ai/shared/retry.py\", line 38, in retry_func\n    return func(*args, **kwargs)\n  File \"/usr/local/lib/python3.10/site-packages/mage_ai/data_preparation/executors/block_executor.py\", line 587, in __execute_with_retry\n    return self._execute(\n  File \"/usr/local/lib/python3.10/site-packages/mage_ai/data_preparation/executors/block_executor.py\", line 1075, in _execute\n    result = self.block.execute_sync(\n  File \"/usr/local/lib/python3.10/site-packages/mage_ai/data_preparation/models/block/__init__.py\", line 1312, in execute_sync\n    raise err\n  File \"/usr/local/lib/python3.10/site-packages/mage_ai/data_preparation/models/block/__init__.py\", line 1221, in execute_sync\n    output = self.execute_block(\n  File \"/usr/local/lib/python3.10/site-packages/mage_ai/data_preparation/models/block/__init__.py\", line 1527, in execute_block\n    outputs = self._execute_block(\n  File \"/usr/local/lib/python3.10/site-packages/mage_ai/data_preparation/models/block/__init__.py\", line 1683, in _execute_block\n    outputs = self.execute_block_function(\n  File \"/usr/local/lib/python3.10/site-packages/mage_ai/data_preparation/models/block/__init__.py\", line 1722, in execute_block_function\n    output = block_function_updated(*input_vars, **global_vars)\n  File \"<string>\", line 58, in load_data\n  File \"/usr/local/lib/python3.10/site-packages/dlt/pipeline/pipeline.py\", line 193, in _wrap\n    step_info = f(self, *args, **kwargs)\n  File \"/usr/local/lib/python3.10/site-packages/dlt/pipeline/pipeline.py\", line 238, in _wrap\n    return f(self, *args, **kwargs)\n  File \"/usr/local/lib/python3.10/site-packages/dlt/pipeline/pipeline.py\", line 619, in run\n    self.extract(\n  File \"/usr/local/lib/python3.10/site-packages/dlt/pipeline/pipeline.py\", line 193, in _wrap\n    step_info = f(self, *args, **kwargs)\n  File \"/usr/local/lib/python3.10/site-packages/dlt/pipeline/pipeline.py\", line 164, in _wrap\n    rv = f(self, *args, **kwargs)\n  File \"/usr/local/lib/python3.10/site-packages/dlt/pipeline/pipeline.py\", line 151, in _wrap\n    return f(self, *args, **kwargs)\n  File \"/usr/local/lib/python3.10/site-packages/dlt/pipeline/pipeline.py\", line 238, in _wrap\n    return f(self, *args, **kwargs)\n  File \"/usr/local/lib/python3.10/site-packages/dlt/pipeline/pipeline.py\", line 403, in extract\n    raise PipelineStepFailed(\ndlt.pipeline.exceptions.PipelineStepFailed: Pipeline execution failed at stage extract when processing package 1713119017.476216 with exception:\n\n<class 'dlt.extract.exceptions.ResourceExtractionError'>\nIn processing pipe src_daily_standings: extraction of resource src_daily_standings in generator load_daily_standings caused an exception: ('Connection aborted.', RemoteDisconnected('Remote end closed connection without response'))\n"], "error_stack": [["  File \"/usr/local/bin/mage\", line 8, in <module>\n    sys.exit(app())\n", "  File \"/usr/local/lib/python3.10/site-packages/typer/main.py\", line 311, in __call__\n    return get_command(self)(*args, **kwargs)\n", "  File \"/usr/local/lib/python3.10/site-packages/click/core.py\", line 1130, in __call__\n    return self.main(*args, **kwargs)\n", "  File \"/usr/local/lib/python3.10/site-packages/typer/core.py\", line 778, in main\n    return _main(\n", "  File \"/usr/local/lib/python3.10/site-packages/typer/core.py\", line 216, in _main\n    rv = self.invoke(ctx)\n", "  File \"/usr/local/lib/python3.10/site-packages/click/core.py\", line 1657, in invoke\n    return _process_result(sub_ctx.command.invoke(sub_ctx))\n", "  File \"/usr/local/lib/python3.10/site-packages/click/core.py\", line 1404, in invoke\n    return ctx.invoke(self.callback, **ctx.params)\n", "  File \"/usr/local/lib/python3.10/site-packages/click/core.py\", line 760, in invoke\n    return __callback(*args, **kwargs)\n", "  File \"/usr/local/lib/python3.10/site-packages/typer/main.py\", line 683, in wrapper\n    return callback(**use_params)  # type: ignore\n", "  File \"/usr/local/lib/python3.10/site-packages/mage_ai/cli/main.py\", line 163, in start\n    start_server(\n", "  File \"/usr/local/lib/python3.10/site-packages/mage_ai/server/server.py\", line 659, in start_server\n    scheduler_manager.start_scheduler()\n", "  File \"/usr/local/lib/python3.10/site-packages/mage_ai/server/scheduler_manager.py\", line 87, in start_scheduler\n    proc.start()\n", "  File \"/usr/local/lib/python3.10/multiprocessing/process.py\", line 121, in start\n    self._popen = self._Popen(self)\n", "  File \"/usr/local/lib/python3.10/multiprocessing/context.py\", line 224, in _Popen\n    return _default_context.get_context().Process._Popen(process_obj)\n", "  File \"/usr/local/lib/python3.10/multiprocessing/context.py\", line 281, in _Popen\n    return Popen(process_obj)\n", "  File \"/usr/local/lib/python3.10/multiprocessing/popen_fork.py\", line 19, in __init__\n    self._launch(process_obj)\n", "  File \"/usr/local/lib/python3.10/multiprocessing/popen_fork.py\", line 71, in _launch\n    code = process_obj._bootstrap(parent_sentinel=child_r)\n", "  File \"/usr/local/lib/python3.10/multiprocessing/process.py\", line 314, in _bootstrap\n    self.run()\n", "  File \"/usr/local/lib/python3.10/multiprocessing/process.py\", line 108, in run\n    self._target(*self._args, **self._kwargs)\n", "  File \"/usr/local/lib/python3.10/site-packages/mage_ai/orchestration/db/process.py\", line 15, in start_session_and_run\n    results = target(*args)\n", "  File \"/usr/local/lib/python3.10/site-packages/mage_ai/server/scheduler_manager.py\", line 50, in run_scheduler\n    LoopTimeTrigger().start()\n", "  File \"/usr/local/lib/python3.10/site-packages/mage_ai/orchestration/triggers/loop_time_trigger.py\", line 14, in start\n    self.run()\n", "  File \"/usr/local/lib/python3.10/site-packages/mage_ai/orchestration/triggers/time_trigger.py\", line 11, in run\n    schedule_all()\n", "  File \"/usr/local/lib/python3.10/site-packages/mage_ai/orchestration/pipeline_scheduler_original.py\", line 1552, in schedule_all\n    PipelineScheduler(r).start()\n", "  File \"/usr/local/lib/python3.10/site-packages/mage_ai/orchestration/db/__init__.py\", line 149, in func_with_rollback\n    return func(*args, **kwargs)\n", "  File \"/usr/local/lib/python3.10/site-packages/mage_ai/orchestration/pipeline_scheduler_original.py\", line 182, in start\n    self.schedule()\n", "  File \"/usr/local/lib/python3.10/site-packages/mage_ai/orchestration/db/__init__.py\", line 149, in func_with_rollback\n    return func(*args, **kwargs)\n", "  File \"/usr/local/lib/python3.10/site-packages/mage_ai/orchestration/pipeline_scheduler_original.py\", line 319, in schedule\n    self.__schedule_blocks(block_runs)\n", "  File \"/usr/local/lib/python3.10/site-packages/mage_ai/orchestration/pipeline_scheduler_original.py\", line 581, in __schedule_blocks\n    job_manager.add_job(\n", "  File \"/usr/local/lib/python3.10/site-packages/mage_ai/orchestration/job_manager.py\", line 27, in add_job\n    self.queue.enqueue(job_id, target, *args, **kwargs)\n", "  File \"/usr/local/lib/python3.10/site-packages/mage_ai/orchestration/queue/process_queue.py\", line 107, in enqueue\n    self.start_worker_pool()\n", "  File \"/usr/local/lib/python3.10/site-packages/mage_ai/orchestration/queue/process_queue.py\", line 173, in start_worker_pool\n    self.worker_pool_proc.start()\n", "  File \"/usr/local/lib/python3.10/multiprocessing/process.py\", line 121, in start\n    self._popen = self._Popen(self)\n", "  File \"/usr/local/lib/python3.10/multiprocessing/context.py\", line 224, in _Popen\n    return _default_context.get_context().Process._Popen(process_obj)\n", "  File \"/usr/local/lib/python3.10/multiprocessing/context.py\", line 281, in _Popen\n    return Popen(process_obj)\n", "  File \"/usr/local/lib/python3.10/multiprocessing/popen_fork.py\", line 19, in __init__\n    self._launch(process_obj)\n", "  File \"/usr/local/lib/python3.10/multiprocessing/popen_fork.py\", line 71, in _launch\n    code = process_obj._bootstrap(parent_sentinel=child_r)\n", "  File \"/usr/local/lib/python3.10/multiprocessing/process.py\", line 314, in _bootstrap\n    self.run()\n", "  File \"/usr/local/lib/python3.10/multiprocessing/process.py\", line 108, in run\n    self._target(*self._args, **self._kwargs)\n", "  File \"/usr/local/lib/python3.10/site-packages/mage_ai/orchestration/queue/process_queue.py\", line 275, in poll_job_and_execute\n    worker.start()\n", "  File \"/usr/local/lib/python3.10/multiprocessing/process.py\", line 121, in start\n    self._popen = self._Popen(self)\n", "  File \"/usr/local/lib/python3.10/multiprocessing/context.py\", line 224, in _Popen\n    return _default_context.get_context().Process._Popen(process_obj)\n", "  File \"/usr/local/lib/python3.10/multiprocessing/context.py\", line 281, in _Popen\n    return Popen(process_obj)\n", "  File \"/usr/local/lib/python3.10/multiprocessing/popen_fork.py\", line 19, in __init__\n    self._launch(process_obj)\n", "  File \"/usr/local/lib/python3.10/multiprocessing/popen_fork.py\", line 71, in _launch\n    code = process_obj._bootstrap(parent_sentinel=child_r)\n", "  File \"/usr/local/lib/python3.10/multiprocessing/process.py\", line 314, in _bootstrap\n    self.run()\n", "  File \"/usr/local/lib/python3.10/site-packages/newrelic/api/background_task.py\", line 117, in wrapper\n    return wrapped(*args, **kwargs)\n", "  File \"/usr/local/lib/python3.10/site-packages/mage_ai/orchestration/queue/process_queue.py\", line 240, in run\n    start_session_and_run(args[1], *args[2], **args[3])\n", "  File \"/usr/local/lib/python3.10/site-packages/mage_ai/orchestration/db/process.py\", line 15, in start_session_and_run\n    results = target(*args)\n", "  File \"/usr/local/lib/python3.10/site-packages/mage_ai/orchestration/pipeline_scheduler_original.py\", line 1105, in run_block\n    return ExecutorFactory.get_block_executor(\n", "  File \"/usr/local/lib/python3.10/site-packages/mage_ai/data_preparation/executors/block_executor.py\", line 612, in execute\n    result = __execute_with_retry()\n", "  File \"/usr/local/lib/python3.10/site-packages/mage_ai/shared/retry.py\", line 46, in retry_func\n    logger.warning(\n", "  File \"/usr/local/lib/python3.10/site-packages/mage_ai/data_preparation/logging/logger.py\", line 39, in warning\n    self.__send_message('warning', message, **kwargs)\n", "  File \"/usr/local/lib/python3.10/site-packages/mage_ai/data_preparation/logging/logger.py\", line 59, in __send_message\n    data['error_stack'] = traceback.format_stack(),\n"]], "error_stacktrace": ["Pipeline execution failed at stage extract when processing package 1713119017.476216 with exception:\n\n<class 'dlt.extract.exceptions.ResourceExtractionError'>\nIn processing pipe src_daily_standings: extraction of resource src_daily_standings in generator load_daily_standings caused an exception: ('Connection aborted.', RemoteDisconnected('Remote end closed connection without response'))"]}
2024-04-14T18:24:47 {"block_run_id": 13, "block_uuid": "api_to_bigquery", "pipeline_run_id": 6, "pipeline_schedule_id": 6, "pipeline_uuid": "seed_bq", "hostname": "ee16a9cfd313", "block_type": "data_loader", "level": "EXCEPTION", "message": "Failed to execute block api_to_bigquery", "timestamp": 1713119087.35668, "uuid": "faf8621904774b73b13494413650db9c", "error": ["Traceback (most recent call last):\n  File \"/usr/local/lib/python3.10/site-packages/urllib3/connectionpool.py\", line 715, in urlopen\n    httplib_response = self._make_request(\n  File \"/usr/local/lib/python3.10/site-packages/urllib3/connectionpool.py\", line 467, in _make_request\n    six.raise_from(e, None)\n  File \"<string>\", line 3, in raise_from\n  File \"/usr/local/lib/python3.10/site-packages/urllib3/connectionpool.py\", line 462, in _make_request\n    httplib_response = conn.getresponse()\n  File \"/usr/local/lib/python3.10/http/client.py\", line 1375, in getresponse\n    response.begin()\n  File \"/usr/local/lib/python3.10/http/client.py\", line 318, in begin\n    version, status, reason = self._read_status()\n  File \"/usr/local/lib/python3.10/http/client.py\", line 287, in _read_status\n    raise RemoteDisconnected(\"Remote end closed connection without\"\nhttp.client.RemoteDisconnected: Remote end closed connection without response\n\nDuring handling of the above exception, another exception occurred:\n\nTraceback (most recent call last):\n  File \"/usr/local/lib/python3.10/site-packages/requests/adapters.py\", line 486, in send\n    resp = conn.urlopen(\n  File \"/usr/local/lib/python3.10/site-packages/urllib3/connectionpool.py\", line 799, in urlopen\n    retries = retries.increment(\n  File \"/usr/local/lib/python3.10/site-packages/urllib3/util/retry.py\", line 550, in increment\n    raise six.reraise(type(error), error, _stacktrace)\n  File \"/usr/local/lib/python3.10/site-packages/urllib3/packages/six.py\", line 769, in reraise\n    raise value.with_traceback(tb)\n  File \"/usr/local/lib/python3.10/site-packages/urllib3/connectionpool.py\", line 715, in urlopen\n    httplib_response = self._make_request(\n  File \"/usr/local/lib/python3.10/site-packages/urllib3/connectionpool.py\", line 467, in _make_request\n    six.raise_from(e, None)\n  File \"<string>\", line 3, in raise_from\n  File \"/usr/local/lib/python3.10/site-packages/urllib3/connectionpool.py\", line 462, in _make_request\n    httplib_response = conn.getresponse()\n  File \"/usr/local/lib/python3.10/http/client.py\", line 1375, in getresponse\n    response.begin()\n  File \"/usr/local/lib/python3.10/http/client.py\", line 318, in begin\n    version, status, reason = self._read_status()\n  File \"/usr/local/lib/python3.10/http/client.py\", line 287, in _read_status\n    raise RemoteDisconnected(\"Remote end closed connection without\"\nurllib3.exceptions.ProtocolError: ('Connection aborted.', RemoteDisconnected('Remote end closed connection without response'))\n\nDuring handling of the above exception, another exception occurred:\n\nTraceback (most recent call last):\n  File \"/usr/local/lib/python3.10/site-packages/dlt/extract/pipe.py\", line 837, in _get_source_item\n    if (item := next(gen)) is not None:\n  File \"/home/src/./mage_nba_watchability_index/utils/dlt_resources/dlt_nba.py\", line 151, in load_daily_standings\n    ec = sb.ScoreboardV2(day_offset=-day_offset).east_conf_standings_by_day.get_data_frame()\n  File \"/usr/local/lib/python3.10/site-packages/nba_api/stats/endpoints/scoreboardv2.py\", line 159, in __init__\n    self.get_request()\n  File \"/usr/local/lib/python3.10/site-packages/nba_api/stats/endpoints/scoreboardv2.py\", line 162, in get_request\n    self.nba_response = NBAStatsHTTP().send_api_request(\n  File \"/usr/local/lib/python3.10/site-packages/nba_api/library/http.py\", line 146, in send_api_request\n    response = requests.get(\n  File \"/usr/local/lib/python3.10/site-packages/requests/api.py\", line 73, in get\n    return request(\"get\", url, params=params, **kwargs)\n  File \"/usr/local/lib/python3.10/site-packages/requests/api.py\", line 59, in request\n    return session.request(method=method, url=url, **kwargs)\n  File \"/usr/local/lib/python3.10/site-packages/requests/sessions.py\", line 589, in request\n    resp = self.send(prep, **send_kwargs)\n  File \"/usr/local/lib/python3.10/site-packages/requests/sessions.py\", line 703, in send\n    r = adapter.send(request, **kwargs)\n  File \"/usr/local/lib/python3.10/site-packages/requests/adapters.py\", line 501, in send\n    raise ConnectionError(err, request=request)\nrequests.exceptions.ConnectionError: ('Connection aborted.', RemoteDisconnected('Remote end closed connection without response'))\n\nThe above exception was the direct cause of the following exception:\n\nTraceback (most recent call last):\n  File \"/usr/local/lib/python3.10/site-packages/dlt/pipeline/pipeline.py\", line 391, in extract\n    self._extract_source(extract_step, source, max_parallel_items, workers)\n  File \"/usr/local/lib/python3.10/site-packages/dlt/pipeline/pipeline.py\", line 1028, in _extract_source\n    load_id = extract.extract(source, max_parallel_items, workers)\n  File \"/usr/local/lib/python3.10/site-packages/dlt/extract/extract.py\", line 341, in extract\n    self._extract_single_source(\n  File \"/usr/local/lib/python3.10/site-packages/dlt/extract/extract.py\", line 271, in _extract_single_source\n    for pipe_item in pipes:\n  File \"/usr/local/lib/python3.10/site-packages/dlt/extract/pipe.py\", line 605, in __next__\n    pipe_item = self._get_source_item()\n  File \"/usr/local/lib/python3.10/site-packages/dlt/extract/pipe.py\", line 863, in _get_source_item\n    raise ResourceExtractionError(pipe.name, gen, str(ex), \"generator\") from ex\ndlt.extract.exceptions.ResourceExtractionError: In processing pipe src_daily_standings: extraction of resource src_daily_standings in generator load_daily_standings caused an exception: ('Connection aborted.', RemoteDisconnected('Remote end closed connection without response'))\n\nThe above exception was the direct cause of the following exception:\n\nTraceback (most recent call last):\n  File \"/usr/local/lib/python3.10/site-packages/mage_ai/data_preparation/executors/block_executor.py\", line 612, in execute\n    result = __execute_with_retry()\n  File \"/usr/local/lib/python3.10/site-packages/mage_ai/shared/retry.py\", line 54, in retry_func\n    raise e\n  File \"/usr/local/lib/python3.10/site-packages/mage_ai/shared/retry.py\", line 38, in retry_func\n    return func(*args, **kwargs)\n  File \"/usr/local/lib/python3.10/site-packages/mage_ai/data_preparation/executors/block_executor.py\", line 587, in __execute_with_retry\n    return self._execute(\n  File \"/usr/local/lib/python3.10/site-packages/mage_ai/data_preparation/executors/block_executor.py\", line 1075, in _execute\n    result = self.block.execute_sync(\n  File \"/usr/local/lib/python3.10/site-packages/mage_ai/data_preparation/models/block/__init__.py\", line 1312, in execute_sync\n    raise err\n  File \"/usr/local/lib/python3.10/site-packages/mage_ai/data_preparation/models/block/__init__.py\", line 1221, in execute_sync\n    output = self.execute_block(\n  File \"/usr/local/lib/python3.10/site-packages/mage_ai/data_preparation/models/block/__init__.py\", line 1527, in execute_block\n    outputs = self._execute_block(\n  File \"/usr/local/lib/python3.10/site-packages/mage_ai/data_preparation/models/block/__init__.py\", line 1683, in _execute_block\n    outputs = self.execute_block_function(\n  File \"/usr/local/lib/python3.10/site-packages/mage_ai/data_preparation/models/block/__init__.py\", line 1722, in execute_block_function\n    output = block_function_updated(*input_vars, **global_vars)\n  File \"<string>\", line 58, in load_data\n  File \"/usr/local/lib/python3.10/site-packages/dlt/pipeline/pipeline.py\", line 193, in _wrap\n    step_info = f(self, *args, **kwargs)\n  File \"/usr/local/lib/python3.10/site-packages/dlt/pipeline/pipeline.py\", line 238, in _wrap\n    return f(self, *args, **kwargs)\n  File \"/usr/local/lib/python3.10/site-packages/dlt/pipeline/pipeline.py\", line 619, in run\n    self.extract(\n  File \"/usr/local/lib/python3.10/site-packages/dlt/pipeline/pipeline.py\", line 193, in _wrap\n    step_info = f(self, *args, **kwargs)\n  File \"/usr/local/lib/python3.10/site-packages/dlt/pipeline/pipeline.py\", line 164, in _wrap\n    rv = f(self, *args, **kwargs)\n  File \"/usr/local/lib/python3.10/site-packages/dlt/pipeline/pipeline.py\", line 151, in _wrap\n    return f(self, *args, **kwargs)\n  File \"/usr/local/lib/python3.10/site-packages/dlt/pipeline/pipeline.py\", line 238, in _wrap\n    return f(self, *args, **kwargs)\n  File \"/usr/local/lib/python3.10/site-packages/dlt/pipeline/pipeline.py\", line 403, in extract\n    raise PipelineStepFailed(\ndlt.pipeline.exceptions.PipelineStepFailed: Pipeline execution failed at stage extract when processing package 1713119017.476216 with exception:\n\n<class 'dlt.extract.exceptions.ResourceExtractionError'>\nIn processing pipe src_daily_standings: extraction of resource src_daily_standings in generator load_daily_standings caused an exception: ('Connection aborted.', RemoteDisconnected('Remote end closed connection without response'))\n"], "error_stack": [["  File \"/usr/local/bin/mage\", line 8, in <module>\n    sys.exit(app())\n", "  File \"/usr/local/lib/python3.10/site-packages/typer/main.py\", line 311, in __call__\n    return get_command(self)(*args, **kwargs)\n", "  File \"/usr/local/lib/python3.10/site-packages/click/core.py\", line 1130, in __call__\n    return self.main(*args, **kwargs)\n", "  File \"/usr/local/lib/python3.10/site-packages/typer/core.py\", line 778, in main\n    return _main(\n", "  File \"/usr/local/lib/python3.10/site-packages/typer/core.py\", line 216, in _main\n    rv = self.invoke(ctx)\n", "  File \"/usr/local/lib/python3.10/site-packages/click/core.py\", line 1657, in invoke\n    return _process_result(sub_ctx.command.invoke(sub_ctx))\n", "  File \"/usr/local/lib/python3.10/site-packages/click/core.py\", line 1404, in invoke\n    return ctx.invoke(self.callback, **ctx.params)\n", "  File \"/usr/local/lib/python3.10/site-packages/click/core.py\", line 760, in invoke\n    return __callback(*args, **kwargs)\n", "  File \"/usr/local/lib/python3.10/site-packages/typer/main.py\", line 683, in wrapper\n    return callback(**use_params)  # type: ignore\n", "  File \"/usr/local/lib/python3.10/site-packages/mage_ai/cli/main.py\", line 163, in start\n    start_server(\n", "  File \"/usr/local/lib/python3.10/site-packages/mage_ai/server/server.py\", line 659, in start_server\n    scheduler_manager.start_scheduler()\n", "  File \"/usr/local/lib/python3.10/site-packages/mage_ai/server/scheduler_manager.py\", line 87, in start_scheduler\n    proc.start()\n", "  File \"/usr/local/lib/python3.10/multiprocessing/process.py\", line 121, in start\n    self._popen = self._Popen(self)\n", "  File \"/usr/local/lib/python3.10/multiprocessing/context.py\", line 224, in _Popen\n    return _default_context.get_context().Process._Popen(process_obj)\n", "  File \"/usr/local/lib/python3.10/multiprocessing/context.py\", line 281, in _Popen\n    return Popen(process_obj)\n", "  File \"/usr/local/lib/python3.10/multiprocessing/popen_fork.py\", line 19, in __init__\n    self._launch(process_obj)\n", "  File \"/usr/local/lib/python3.10/multiprocessing/popen_fork.py\", line 71, in _launch\n    code = process_obj._bootstrap(parent_sentinel=child_r)\n", "  File \"/usr/local/lib/python3.10/multiprocessing/process.py\", line 314, in _bootstrap\n    self.run()\n", "  File \"/usr/local/lib/python3.10/multiprocessing/process.py\", line 108, in run\n    self._target(*self._args, **self._kwargs)\n", "  File \"/usr/local/lib/python3.10/site-packages/mage_ai/orchestration/db/process.py\", line 15, in start_session_and_run\n    results = target(*args)\n", "  File \"/usr/local/lib/python3.10/site-packages/mage_ai/server/scheduler_manager.py\", line 50, in run_scheduler\n    LoopTimeTrigger().start()\n", "  File \"/usr/local/lib/python3.10/site-packages/mage_ai/orchestration/triggers/loop_time_trigger.py\", line 14, in start\n    self.run()\n", "  File \"/usr/local/lib/python3.10/site-packages/mage_ai/orchestration/triggers/time_trigger.py\", line 11, in run\n    schedule_all()\n", "  File \"/usr/local/lib/python3.10/site-packages/mage_ai/orchestration/pipeline_scheduler_original.py\", line 1552, in schedule_all\n    PipelineScheduler(r).start()\n", "  File \"/usr/local/lib/python3.10/site-packages/mage_ai/orchestration/db/__init__.py\", line 149, in func_with_rollback\n    return func(*args, **kwargs)\n", "  File \"/usr/local/lib/python3.10/site-packages/mage_ai/orchestration/pipeline_scheduler_original.py\", line 182, in start\n    self.schedule()\n", "  File \"/usr/local/lib/python3.10/site-packages/mage_ai/orchestration/db/__init__.py\", line 149, in func_with_rollback\n    return func(*args, **kwargs)\n", "  File \"/usr/local/lib/python3.10/site-packages/mage_ai/orchestration/pipeline_scheduler_original.py\", line 319, in schedule\n    self.__schedule_blocks(block_runs)\n", "  File \"/usr/local/lib/python3.10/site-packages/mage_ai/orchestration/pipeline_scheduler_original.py\", line 581, in __schedule_blocks\n    job_manager.add_job(\n", "  File \"/usr/local/lib/python3.10/site-packages/mage_ai/orchestration/job_manager.py\", line 27, in add_job\n    self.queue.enqueue(job_id, target, *args, **kwargs)\n", "  File \"/usr/local/lib/python3.10/site-packages/mage_ai/orchestration/queue/process_queue.py\", line 107, in enqueue\n    self.start_worker_pool()\n", "  File \"/usr/local/lib/python3.10/site-packages/mage_ai/orchestration/queue/process_queue.py\", line 173, in start_worker_pool\n    self.worker_pool_proc.start()\n", "  File \"/usr/local/lib/python3.10/multiprocessing/process.py\", line 121, in start\n    self._popen = self._Popen(self)\n", "  File \"/usr/local/lib/python3.10/multiprocessing/context.py\", line 224, in _Popen\n    return _default_context.get_context().Process._Popen(process_obj)\n", "  File \"/usr/local/lib/python3.10/multiprocessing/context.py\", line 281, in _Popen\n    return Popen(process_obj)\n", "  File \"/usr/local/lib/python3.10/multiprocessing/popen_fork.py\", line 19, in __init__\n    self._launch(process_obj)\n", "  File \"/usr/local/lib/python3.10/multiprocessing/popen_fork.py\", line 71, in _launch\n    code = process_obj._bootstrap(parent_sentinel=child_r)\n", "  File \"/usr/local/lib/python3.10/multiprocessing/process.py\", line 314, in _bootstrap\n    self.run()\n", "  File \"/usr/local/lib/python3.10/multiprocessing/process.py\", line 108, in run\n    self._target(*self._args, **self._kwargs)\n", "  File \"/usr/local/lib/python3.10/site-packages/mage_ai/orchestration/queue/process_queue.py\", line 275, in poll_job_and_execute\n    worker.start()\n", "  File \"/usr/local/lib/python3.10/multiprocessing/process.py\", line 121, in start\n    self._popen = self._Popen(self)\n", "  File \"/usr/local/lib/python3.10/multiprocessing/context.py\", line 224, in _Popen\n    return _default_context.get_context().Process._Popen(process_obj)\n", "  File \"/usr/local/lib/python3.10/multiprocessing/context.py\", line 281, in _Popen\n    return Popen(process_obj)\n", "  File \"/usr/local/lib/python3.10/multiprocessing/popen_fork.py\", line 19, in __init__\n    self._launch(process_obj)\n", "  File \"/usr/local/lib/python3.10/multiprocessing/popen_fork.py\", line 71, in _launch\n    code = process_obj._bootstrap(parent_sentinel=child_r)\n", "  File \"/usr/local/lib/python3.10/multiprocessing/process.py\", line 314, in _bootstrap\n    self.run()\n", "  File \"/usr/local/lib/python3.10/site-packages/newrelic/api/background_task.py\", line 117, in wrapper\n    return wrapped(*args, **kwargs)\n", "  File \"/usr/local/lib/python3.10/site-packages/mage_ai/orchestration/queue/process_queue.py\", line 240, in run\n    start_session_and_run(args[1], *args[2], **args[3])\n", "  File \"/usr/local/lib/python3.10/site-packages/mage_ai/orchestration/db/process.py\", line 15, in start_session_and_run\n    results = target(*args)\n", "  File \"/usr/local/lib/python3.10/site-packages/mage_ai/orchestration/pipeline_scheduler_original.py\", line 1105, in run_block\n    return ExecutorFactory.get_block_executor(\n", "  File \"/usr/local/lib/python3.10/site-packages/mage_ai/data_preparation/executors/block_executor.py\", line 614, in execute\n    self.logger.exception(\n", "  File \"/usr/local/lib/python3.10/site-packages/mage_ai/data_preparation/logging/logger.py\", line 30, in exception\n    self.__send_message('exception', message, **kwargs)\n", "  File \"/usr/local/lib/python3.10/site-packages/mage_ai/data_preparation/logging/logger.py\", line 59, in __send_message\n    data['error_stack'] = traceback.format_stack(),\n"]], "error_stacktrace": ["Pipeline execution failed at stage extract when processing package 1713119017.476216 with exception:\n\n<class 'dlt.extract.exceptions.ResourceExtractionError'>\nIn processing pipe src_daily_standings: extraction of resource src_daily_standings in generator load_daily_standings caused an exception: ('Connection aborted.', RemoteDisconnected('Remote end closed connection without response'))"]}
Traceback (most recent call last):
  File "/usr/local/lib/python3.10/site-packages/urllib3/connectionpool.py", line 715, in urlopen
    httplib_response = self._make_request(
  File "/usr/local/lib/python3.10/site-packages/urllib3/connectionpool.py", line 467, in _make_request
    six.raise_from(e, None)
  File "<string>", line 3, in raise_from
  File "/usr/local/lib/python3.10/site-packages/urllib3/connectionpool.py", line 462, in _make_request
    httplib_response = conn.getresponse()
  File "/usr/local/lib/python3.10/http/client.py", line 1375, in getresponse
    response.begin()
  File "/usr/local/lib/python3.10/http/client.py", line 318, in begin
    version, status, reason = self._read_status()
  File "/usr/local/lib/python3.10/http/client.py", line 287, in _read_status
    raise RemoteDisconnected("Remote end closed connection without"
http.client.RemoteDisconnected: Remote end closed connection without response

During handling of the above exception, another exception occurred:

Traceback (most recent call last):
  File "/usr/local/lib/python3.10/site-packages/requests/adapters.py", line 486, in send
    resp = conn.urlopen(
  File "/usr/local/lib/python3.10/site-packages/urllib3/connectionpool.py", line 799, in urlopen
    retries = retries.increment(
  File "/usr/local/lib/python3.10/site-packages/urllib3/util/retry.py", line 550, in increment
    raise six.reraise(type(error), error, _stacktrace)
  File "/usr/local/lib/python3.10/site-packages/urllib3/packages/six.py", line 769, in reraise
    raise value.with_traceback(tb)
  File "/usr/local/lib/python3.10/site-packages/urllib3/connectionpool.py", line 715, in urlopen
    httplib_response = self._make_request(
  File "/usr/local/lib/python3.10/site-packages/urllib3/connectionpool.py", line 467, in _make_request
    six.raise_from(e, None)
  File "<string>", line 3, in raise_from
  File "/usr/local/lib/python3.10/site-packages/urllib3/connectionpool.py", line 462, in _make_request
    httplib_response = conn.getresponse()
  File "/usr/local/lib/python3.10/http/client.py", line 1375, in getresponse
    response.begin()
  File "/usr/local/lib/python3.10/http/client.py", line 318, in begin
    version, status, reason = self._read_status()
  File "/usr/local/lib/python3.10/http/client.py", line 287, in _read_status
    raise RemoteDisconnected("Remote end closed connection without"
urllib3.exceptions.ProtocolError: ('Connection aborted.', RemoteDisconnected('Remote end closed connection without response'))

During handling of the above exception, another exception occurred:

Traceback (most recent call last):
  File "/usr/local/lib/python3.10/site-packages/dlt/extract/pipe.py", line 837, in _get_source_item
    if (item := next(gen)) is not None:
  File "/home/src/./mage_nba_watchability_index/utils/dlt_resources/dlt_nba.py", line 151, in load_daily_standings
    ec = sb.ScoreboardV2(day_offset=-day_offset).east_conf_standings_by_day.get_data_frame()
  File "/usr/local/lib/python3.10/site-packages/nba_api/stats/endpoints/scoreboardv2.py", line 159, in __init__
    self.get_request()
  File "/usr/local/lib/python3.10/site-packages/nba_api/stats/endpoints/scoreboardv2.py", line 162, in get_request
    self.nba_response = NBAStatsHTTP().send_api_request(
  File "/usr/local/lib/python3.10/site-packages/nba_api/library/http.py", line 146, in send_api_request
    response = requests.get(
  File "/usr/local/lib/python3.10/site-packages/requests/api.py", line 73, in get
    return request("get", url, params=params, **kwargs)
  File "/usr/local/lib/python3.10/site-packages/requests/api.py", line 59, in request
    return session.request(method=method, url=url, **kwargs)
  File "/usr/local/lib/python3.10/site-packages/requests/sessions.py", line 589, in request
    resp = self.send(prep, **send_kwargs)
  File "/usr/local/lib/python3.10/site-packages/requests/sessions.py", line 703, in send
    r = adapter.send(request, **kwargs)
  File "/usr/local/lib/python3.10/site-packages/requests/adapters.py", line 501, in send
    raise ConnectionError(err, request=request)
requests.exceptions.ConnectionError: ('Connection aborted.', RemoteDisconnected('Remote end closed connection without response'))

The above exception was the direct cause of the following exception:

Traceback (most recent call last):
  File "/usr/local/lib/python3.10/site-packages/dlt/pipeline/pipeline.py", line 391, in extract
    self._extract_source(extract_step, source, max_parallel_items, workers)
  File "/usr/local/lib/python3.10/site-packages/dlt/pipeline/pipeline.py", line 1028, in _extract_source
    load_id = extract.extract(source, max_parallel_items, workers)
  File "/usr/local/lib/python3.10/site-packages/dlt/extract/extract.py", line 341, in extract
    self._extract_single_source(
  File "/usr/local/lib/python3.10/site-packages/dlt/extract/extract.py", line 271, in _extract_single_source
    for pipe_item in pipes:
  File "/usr/local/lib/python3.10/site-packages/dlt/extract/pipe.py", line 605, in __next__
    pipe_item = self._get_source_item()
  File "/usr/local/lib/python3.10/site-packages/dlt/extract/pipe.py", line 863, in _get_source_item
    raise ResourceExtractionError(pipe.name, gen, str(ex), "generator") from ex
dlt.extract.exceptions.ResourceExtractionError: In processing pipe src_daily_standings: extraction of resource src_daily_standings in generator load_daily_standings caused an exception: ('Connection aborted.', RemoteDisconnected('Remote end closed connection without response'))

The above exception was the direct cause of the following exception:

Traceback (most recent call last):
  File "/usr/local/lib/python3.10/site-packages/mage_ai/data_preparation/executors/block_executor.py", line 612, in execute
    result = __execute_with_retry()
  File "/usr/local/lib/python3.10/site-packages/mage_ai/shared/retry.py", line 54, in retry_func
    raise e
  File "/usr/local/lib/python3.10/site-packages/mage_ai/shared/retry.py", line 38, in retry_func
    return func(*args, **kwargs)
  File "/usr/local/lib/python3.10/site-packages/mage_ai/data_preparation/executors/block_executor.py", line 587, in __execute_with_retry
    return self._execute(
  File "/usr/local/lib/python3.10/site-packages/mage_ai/data_preparation/executors/block_executor.py", line 1075, in _execute
    result = self.block.execute_sync(
  File "/usr/local/lib/python3.10/site-packages/mage_ai/data_preparation/models/block/__init__.py", line 1312, in execute_sync
    raise err
  File "/usr/local/lib/python3.10/site-packages/mage_ai/data_preparation/models/block/__init__.py", line 1221, in execute_sync
    output = self.execute_block(
  File "/usr/local/lib/python3.10/site-packages/mage_ai/data_preparation/models/block/__init__.py", line 1527, in execute_block
    outputs = self._execute_block(
  File "/usr/local/lib/python3.10/site-packages/mage_ai/data_preparation/models/block/__init__.py", line 1683, in _execute_block
    outputs = self.execute_block_function(
  File "/usr/local/lib/python3.10/site-packages/mage_ai/data_preparation/models/block/__init__.py", line 1722, in execute_block_function
    output = block_function_updated(*input_vars, **global_vars)
  File "<string>", line 58, in load_data
  File "/usr/local/lib/python3.10/site-packages/dlt/pipeline/pipeline.py", line 193, in _wrap
    step_info = f(self, *args, **kwargs)
  File "/usr/local/lib/python3.10/site-packages/dlt/pipeline/pipeline.py", line 238, in _wrap
    return f(self, *args, **kwargs)
  File "/usr/local/lib/python3.10/site-packages/dlt/pipeline/pipeline.py", line 619, in run
    self.extract(
  File "/usr/local/lib/python3.10/site-packages/dlt/pipeline/pipeline.py", line 193, in _wrap
    step_info = f(self, *args, **kwargs)
  File "/usr/local/lib/python3.10/site-packages/dlt/pipeline/pipeline.py", line 164, in _wrap
    rv = f(self, *args, **kwargs)
  File "/usr/local/lib/python3.10/site-packages/dlt/pipeline/pipeline.py", line 151, in _wrap
    return f(self, *args, **kwargs)
  File "/usr/local/lib/python3.10/site-packages/dlt/pipeline/pipeline.py", line 238, in _wrap
    return f(self, *args, **kwargs)
  File "/usr/local/lib/python3.10/site-packages/dlt/pipeline/pipeline.py", line 403, in extract
    raise PipelineStepFailed(
dlt.pipeline.exceptions.PipelineStepFailed: Pipeline execution failed at stage extract when processing package 1713119017.476216 with exception:

<class 'dlt.extract.exceptions.ResourceExtractionError'>
In processing pipe src_daily_standings: extraction of resource src_daily_standings in generator load_daily_standings caused an exception: ('Connection aborted.', RemoteDisconnected('Remote end closed connection without response'))
