2024-04-14T18:23:11 {"cpu": 0.35498046875, "cpu_total": 8, "cpu_usage": 0.04437255859375, "memory": 3155.0, "memory_total": 9922.0, "memory_usage": 0.31798024591816165, "pipeline_run_id": 6, "pipeline_schedule_id": 6, "pipeline_uuid": "seed_bq", "hostname": "ee16a9cfd313", "level": "INFO", "message": "Pipeline seed_bq for run 6 in schedule 6 is alive.", "timestamp": 1713118991.798607, "uuid": "ea5068ed399041a1819a91f0252d8859"}
2024-04-14T18:23:12 {"cpu": 0.35498046875, "cpu_total": 8, "cpu_usage": 0.04437255859375, "memory": 3193.0, "memory_total": 9922.0, "memory_usage": 0.32181011892763556, "pipeline_run_id": 6, "pipeline_schedule_id": 6, "pipeline_uuid": "seed_bq", "hostname": "ee16a9cfd313", "level": "INFO", "message": "Pipeline seed_bq for run 6 in schedule 6 is alive.", "timestamp": 1713118992.255713, "uuid": "1472d18308ac43e7b9d81fe374c98ba1"}
2024-04-14T18:23:12 {"block_run_id": 13, "block_uuid": "api_to_bigquery", "pipeline_run_id": 6, "pipeline_schedule_id": 6, "pipeline_uuid": "seed_bq", "hostname": "ee16a9cfd313", "level": "INFO", "message": "Execute PipelineRun 6, BlockRun 13: pipeline seed_bq block api_to_bigquery", "timestamp": 1713118992.371367, "uuid": "f7f975c3996944e4935a48ec055b2614"}
2024-04-14T18:23:21 {"cpu": 0.37353515625, "cpu_total": 8, "cpu_usage": 0.04669189453125, "memory": 3359.0, "memory_total": 9922.0, "memory_usage": 0.3385406168111268, "pipeline_run_id": 6, "pipeline_schedule_id": 6, "pipeline_uuid": "seed_bq", "hostname": "ee16a9cfd313", "level": "INFO", "message": "Pipeline seed_bq for run 6 in schedule 6 is alive.", "timestamp": 1713119001.268468, "uuid": "ee3080b4523547af8583493684f5b6b4"}
2024-04-14T18:23:31 {"cpu": 0.38037109375, "cpu_total": 8, "cpu_usage": 0.04754638671875, "memory": 3398.0, "memory_total": 9922.0, "memory_usage": 0.34247127595242893, "pipeline_run_id": 6, "pipeline_schedule_id": 6, "pipeline_uuid": "seed_bq", "hostname": "ee16a9cfd313", "level": "INFO", "message": "Pipeline seed_bq for run 6 in schedule 6 is alive.", "timestamp": 1713119011.457482, "uuid": "473d6e2606af4a03ab5efd7ff7a7d824"}
2024-04-14T18:23:41 {"cpu": 0.392578125, "cpu_total": 8, "cpu_usage": 0.049072265625, "memory": 3405.0, "memory_total": 9922.0, "memory_usage": 0.3431767788752268, "pipeline_run_id": 6, "pipeline_schedule_id": 6, "pipeline_uuid": "seed_bq", "hostname": "ee16a9cfd313", "level": "INFO", "message": "Pipeline seed_bq for run 6 in schedule 6 is alive.", "timestamp": 1713119021.456198, "uuid": "f650ecfc517d485186979cd8f5df2d00"}
2024-04-14T18:23:51 {"cpu": 0.40478515625, "cpu_total": 8, "cpu_usage": 0.05059814453125, "memory": 3409.0, "memory_total": 9922.0, "memory_usage": 0.3435799234025398, "pipeline_run_id": 6, "pipeline_schedule_id": 6, "pipeline_uuid": "seed_bq", "hostname": "ee16a9cfd313", "level": "INFO", "message": "Pipeline seed_bq for run 6 in schedule 6 is alive.", "timestamp": 1713119031.427166, "uuid": "90f25f73842d4b409c26e27b1d541059"}
2024-04-14T18:24:01 {"cpu": 0.39990234375, "cpu_total": 8, "cpu_usage": 0.04998779296875, "memory": 3411.0, "memory_total": 9922.0, "memory_usage": 0.3437814956661963, "pipeline_run_id": 6, "pipeline_schedule_id": 6, "pipeline_uuid": "seed_bq", "hostname": "ee16a9cfd313", "level": "INFO", "message": "Pipeline seed_bq for run 6 in schedule 6 is alive.", "timestamp": 1713119041.423681, "uuid": "97c393948cda451b9d9a32e609734642"}
2024-04-14T18:24:11 {"cpu": 0.40625, "cpu_total": 8, "cpu_usage": 0.05078125, "memory": 3416.0, "memory_total": 9922.0, "memory_usage": 0.34428542632533765, "pipeline_run_id": 6, "pipeline_schedule_id": 6, "pipeline_uuid": "seed_bq", "hostname": "ee16a9cfd313", "level": "INFO", "message": "Pipeline seed_bq for run 6 in schedule 6 is alive.", "timestamp": 1713119051.371469, "uuid": "f4fcf477db6541dfafa4ac863e2f5081"}
2024-04-14T18:24:21 {"cpu": 0.4013671875, "cpu_total": 8, "cpu_usage": 0.0501708984375, "memory": 3421.0, "memory_total": 9922.0, "memory_usage": 0.34478935698447893, "pipeline_run_id": 6, "pipeline_schedule_id": 6, "pipeline_uuid": "seed_bq", "hostname": "ee16a9cfd313", "level": "INFO", "message": "Pipeline seed_bq for run 6 in schedule 6 is alive.", "timestamp": 1713119061.282097, "uuid": "4d957bc0c1b74046ae1385cceb15e628"}
2024-04-14T18:24:31 {"cpu": 0.396484375, "cpu_total": 8, "cpu_usage": 0.049560546875, "memory": 3419.0, "memory_total": 9922.0, "memory_usage": 0.3445877847208224, "pipeline_run_id": 6, "pipeline_schedule_id": 6, "pipeline_uuid": "seed_bq", "hostname": "ee16a9cfd313", "level": "INFO", "message": "Pipeline seed_bq for run 6 in schedule 6 is alive.", "timestamp": 1713119071.273103, "uuid": "89fffa7de1bf48fc851af87467ad0781"}
2024-04-14T18:24:41 {"cpu": 0.3916015625, "cpu_total": 8, "cpu_usage": 0.0489501953125, "memory": 3421.0, "memory_total": 9922.0, "memory_usage": 0.34478935698447893, "pipeline_run_id": 6, "pipeline_schedule_id": 6, "pipeline_uuid": "seed_bq", "hostname": "ee16a9cfd313", "level": "INFO", "message": "Pipeline seed_bq for run 6 in schedule 6 is alive.", "timestamp": 1713119081.153291, "uuid": "f9b2347071954c69b4a576ef43641fd5"}
2024-04-14T18:24:47 {"block_run_id": 13, "block_uuid": "api_to_bigquery", "pipeline_run_id": 6, "pipeline_schedule_id": 6, "pipeline_uuid": "seed_bq", "hostname": "ee16a9cfd313", "level": "EXCEPTION", "message": "BlockRun 13 (block_uuid: api_to_bigquery) failed.", "timestamp": 1713119087.443653, "uuid": "fc5ee59372414fba851bb0ba6b62d228", "error": ["Traceback (most recent call last):\n  File \"/usr/local/lib/python3.10/site-packages/urllib3/connectionpool.py\", line 715, in urlopen\n    httplib_response = self._make_request(\n  File \"/usr/local/lib/python3.10/site-packages/urllib3/connectionpool.py\", line 467, in _make_request\n    six.raise_from(e, None)\n  File \"<string>\", line 3, in raise_from\n  File \"/usr/local/lib/python3.10/site-packages/urllib3/connectionpool.py\", line 462, in _make_request\n    httplib_response = conn.getresponse()\n  File \"/usr/local/lib/python3.10/http/client.py\", line 1375, in getresponse\n    response.begin()\n  File \"/usr/local/lib/python3.10/http/client.py\", line 318, in begin\n    version, status, reason = self._read_status()\n  File \"/usr/local/lib/python3.10/http/client.py\", line 287, in _read_status\n    raise RemoteDisconnected(\"Remote end closed connection without\"\nhttp.client.RemoteDisconnected: Remote end closed connection without response\n\nDuring handling of the above exception, another exception occurred:\n\nTraceback (most recent call last):\n  File \"/usr/local/lib/python3.10/site-packages/requests/adapters.py\", line 486, in send\n    resp = conn.urlopen(\n  File \"/usr/local/lib/python3.10/site-packages/urllib3/connectionpool.py\", line 799, in urlopen\n    retries = retries.increment(\n  File \"/usr/local/lib/python3.10/site-packages/urllib3/util/retry.py\", line 550, in increment\n    raise six.reraise(type(error), error, _stacktrace)\n  File \"/usr/local/lib/python3.10/site-packages/urllib3/packages/six.py\", line 769, in reraise\n    raise value.with_traceback(tb)\n  File \"/usr/local/lib/python3.10/site-packages/urllib3/connectionpool.py\", line 715, in urlopen\n    httplib_response = self._make_request(\n  File \"/usr/local/lib/python3.10/site-packages/urllib3/connectionpool.py\", line 467, in _make_request\n    six.raise_from(e, None)\n  File \"<string>\", line 3, in raise_from\n  File \"/usr/local/lib/python3.10/site-packages/urllib3/connectionpool.py\", line 462, in _make_request\n    httplib_response = conn.getresponse()\n  File \"/usr/local/lib/python3.10/http/client.py\", line 1375, in getresponse\n    response.begin()\n  File \"/usr/local/lib/python3.10/http/client.py\", line 318, in begin\n    version, status, reason = self._read_status()\n  File \"/usr/local/lib/python3.10/http/client.py\", line 287, in _read_status\n    raise RemoteDisconnected(\"Remote end closed connection without\"\nurllib3.exceptions.ProtocolError: ('Connection aborted.', RemoteDisconnected('Remote end closed connection without response'))\n\nDuring handling of the above exception, another exception occurred:\n\nTraceback (most recent call last):\n  File \"/usr/local/lib/python3.10/site-packages/dlt/extract/pipe.py\", line 837, in _get_source_item\n    if (item := next(gen)) is not None:\n  File \"/home/src/./mage_nba_watchability_index/utils/dlt_resources/dlt_nba.py\", line 151, in load_daily_standings\n    ec = sb.ScoreboardV2(day_offset=-day_offset).east_conf_standings_by_day.get_data_frame()\n  File \"/usr/local/lib/python3.10/site-packages/nba_api/stats/endpoints/scoreboardv2.py\", line 159, in __init__\n    self.get_request()\n  File \"/usr/local/lib/python3.10/site-packages/nba_api/stats/endpoints/scoreboardv2.py\", line 162, in get_request\n    self.nba_response = NBAStatsHTTP().send_api_request(\n  File \"/usr/local/lib/python3.10/site-packages/nba_api/library/http.py\", line 146, in send_api_request\n    response = requests.get(\n  File \"/usr/local/lib/python3.10/site-packages/requests/api.py\", line 73, in get\n    return request(\"get\", url, params=params, **kwargs)\n  File \"/usr/local/lib/python3.10/site-packages/requests/api.py\", line 59, in request\n    return session.request(method=method, url=url, **kwargs)\n  File \"/usr/local/lib/python3.10/site-packages/requests/sessions.py\", line 589, in request\n    resp = self.send(prep, **send_kwargs)\n  File \"/usr/local/lib/python3.10/site-packages/requests/sessions.py\", line 703, in send\n    r = adapter.send(request, **kwargs)\n  File \"/usr/local/lib/python3.10/site-packages/requests/adapters.py\", line 501, in send\n    raise ConnectionError(err, request=request)\nrequests.exceptions.ConnectionError: ('Connection aborted.', RemoteDisconnected('Remote end closed connection without response'))\n\nThe above exception was the direct cause of the following exception:\n\nTraceback (most recent call last):\n  File \"/usr/local/lib/python3.10/site-packages/dlt/pipeline/pipeline.py\", line 391, in extract\n    self._extract_source(extract_step, source, max_parallel_items, workers)\n  File \"/usr/local/lib/python3.10/site-packages/dlt/pipeline/pipeline.py\", line 1028, in _extract_source\n    load_id = extract.extract(source, max_parallel_items, workers)\n  File \"/usr/local/lib/python3.10/site-packages/dlt/extract/extract.py\", line 341, in extract\n    self._extract_single_source(\n  File \"/usr/local/lib/python3.10/site-packages/dlt/extract/extract.py\", line 271, in _extract_single_source\n    for pipe_item in pipes:\n  File \"/usr/local/lib/python3.10/site-packages/dlt/extract/pipe.py\", line 605, in __next__\n    pipe_item = self._get_source_item()\n  File \"/usr/local/lib/python3.10/site-packages/dlt/extract/pipe.py\", line 863, in _get_source_item\n    raise ResourceExtractionError(pipe.name, gen, str(ex), \"generator\") from ex\ndlt.extract.exceptions.ResourceExtractionError: In processing pipe src_daily_standings: extraction of resource src_daily_standings in generator load_daily_standings caused an exception: ('Connection aborted.', RemoteDisconnected('Remote end closed connection without response'))\n\nThe above exception was the direct cause of the following exception:\n\nTraceback (most recent call last):\n  File \"/usr/local/lib/python3.10/site-packages/mage_ai/data_preparation/executors/block_executor.py\", line 612, in execute\n    result = __execute_with_retry()\n  File \"/usr/local/lib/python3.10/site-packages/mage_ai/shared/retry.py\", line 54, in retry_func\n    raise e\n  File \"/usr/local/lib/python3.10/site-packages/mage_ai/shared/retry.py\", line 38, in retry_func\n    return func(*args, **kwargs)\n  File \"/usr/local/lib/python3.10/site-packages/mage_ai/data_preparation/executors/block_executor.py\", line 587, in __execute_with_retry\n    return self._execute(\n  File \"/usr/local/lib/python3.10/site-packages/mage_ai/data_preparation/executors/block_executor.py\", line 1075, in _execute\n    result = self.block.execute_sync(\n  File \"/usr/local/lib/python3.10/site-packages/mage_ai/data_preparation/models/block/__init__.py\", line 1312, in execute_sync\n    raise err\n  File \"/usr/local/lib/python3.10/site-packages/mage_ai/data_preparation/models/block/__init__.py\", line 1221, in execute_sync\n    output = self.execute_block(\n  File \"/usr/local/lib/python3.10/site-packages/mage_ai/data_preparation/models/block/__init__.py\", line 1527, in execute_block\n    outputs = self._execute_block(\n  File \"/usr/local/lib/python3.10/site-packages/mage_ai/data_preparation/models/block/__init__.py\", line 1683, in _execute_block\n    outputs = self.execute_block_function(\n  File \"/usr/local/lib/python3.10/site-packages/mage_ai/data_preparation/models/block/__init__.py\", line 1722, in execute_block_function\n    output = block_function_updated(*input_vars, **global_vars)\n  File \"<string>\", line 58, in load_data\n  File \"/usr/local/lib/python3.10/site-packages/dlt/pipeline/pipeline.py\", line 193, in _wrap\n    step_info = f(self, *args, **kwargs)\n  File \"/usr/local/lib/python3.10/site-packages/dlt/pipeline/pipeline.py\", line 238, in _wrap\n    return f(self, *args, **kwargs)\n  File \"/usr/local/lib/python3.10/site-packages/dlt/pipeline/pipeline.py\", line 619, in run\n    self.extract(\n  File \"/usr/local/lib/python3.10/site-packages/dlt/pipeline/pipeline.py\", line 193, in _wrap\n    step_info = f(self, *args, **kwargs)\n  File \"/usr/local/lib/python3.10/site-packages/dlt/pipeline/pipeline.py\", line 164, in _wrap\n    rv = f(self, *args, **kwargs)\n  File \"/usr/local/lib/python3.10/site-packages/dlt/pipeline/pipeline.py\", line 151, in _wrap\n    return f(self, *args, **kwargs)\n  File \"/usr/local/lib/python3.10/site-packages/dlt/pipeline/pipeline.py\", line 238, in _wrap\n    return f(self, *args, **kwargs)\n  File \"/usr/local/lib/python3.10/site-packages/dlt/pipeline/pipeline.py\", line 403, in extract\n    raise PipelineStepFailed(\ndlt.pipeline.exceptions.PipelineStepFailed: Pipeline execution failed at stage extract when processing package 1713119017.476216 with exception:\n\n<class 'dlt.extract.exceptions.ResourceExtractionError'>\nIn processing pipe src_daily_standings: extraction of resource src_daily_standings in generator load_daily_standings caused an exception: ('Connection aborted.', RemoteDisconnected('Remote end closed connection without response'))\n"], "error_stack": [["  File \"/usr/local/bin/mage\", line 8, in <module>\n    sys.exit(app())\n", "  File \"/usr/local/lib/python3.10/site-packages/typer/main.py\", line 311, in __call__\n    return get_command(self)(*args, **kwargs)\n", "  File \"/usr/local/lib/python3.10/site-packages/click/core.py\", line 1130, in __call__\n    return self.main(*args, **kwargs)\n", "  File \"/usr/local/lib/python3.10/site-packages/typer/core.py\", line 778, in main\n    return _main(\n", "  File \"/usr/local/lib/python3.10/site-packages/typer/core.py\", line 216, in _main\n    rv = self.invoke(ctx)\n", "  File \"/usr/local/lib/python3.10/site-packages/click/core.py\", line 1657, in invoke\n    return _process_result(sub_ctx.command.invoke(sub_ctx))\n", "  File \"/usr/local/lib/python3.10/site-packages/click/core.py\", line 1404, in invoke\n    return ctx.invoke(self.callback, **ctx.params)\n", "  File \"/usr/local/lib/python3.10/site-packages/click/core.py\", line 760, in invoke\n    return __callback(*args, **kwargs)\n", "  File \"/usr/local/lib/python3.10/site-packages/typer/main.py\", line 683, in wrapper\n    return callback(**use_params)  # type: ignore\n", "  File \"/usr/local/lib/python3.10/site-packages/mage_ai/cli/main.py\", line 163, in start\n    start_server(\n", "  File \"/usr/local/lib/python3.10/site-packages/mage_ai/server/server.py\", line 659, in start_server\n    scheduler_manager.start_scheduler()\n", "  File \"/usr/local/lib/python3.10/site-packages/mage_ai/server/scheduler_manager.py\", line 87, in start_scheduler\n    proc.start()\n", "  File \"/usr/local/lib/python3.10/multiprocessing/process.py\", line 121, in start\n    self._popen = self._Popen(self)\n", "  File \"/usr/local/lib/python3.10/multiprocessing/context.py\", line 224, in _Popen\n    return _default_context.get_context().Process._Popen(process_obj)\n", "  File \"/usr/local/lib/python3.10/multiprocessing/context.py\", line 281, in _Popen\n    return Popen(process_obj)\n", "  File \"/usr/local/lib/python3.10/multiprocessing/popen_fork.py\", line 19, in __init__\n    self._launch(process_obj)\n", "  File \"/usr/local/lib/python3.10/multiprocessing/popen_fork.py\", line 71, in _launch\n    code = process_obj._bootstrap(parent_sentinel=child_r)\n", "  File \"/usr/local/lib/python3.10/multiprocessing/process.py\", line 314, in _bootstrap\n    self.run()\n", "  File \"/usr/local/lib/python3.10/multiprocessing/process.py\", line 108, in run\n    self._target(*self._args, **self._kwargs)\n", "  File \"/usr/local/lib/python3.10/site-packages/mage_ai/orchestration/db/process.py\", line 15, in start_session_and_run\n    results = target(*args)\n", "  File \"/usr/local/lib/python3.10/site-packages/mage_ai/server/scheduler_manager.py\", line 50, in run_scheduler\n    LoopTimeTrigger().start()\n", "  File \"/usr/local/lib/python3.10/site-packages/mage_ai/orchestration/triggers/loop_time_trigger.py\", line 14, in start\n    self.run()\n", "  File \"/usr/local/lib/python3.10/site-packages/mage_ai/orchestration/triggers/time_trigger.py\", line 11, in run\n    schedule_all()\n", "  File \"/usr/local/lib/python3.10/site-packages/mage_ai/orchestration/pipeline_scheduler_original.py\", line 1552, in schedule_all\n    PipelineScheduler(r).start()\n", "  File \"/usr/local/lib/python3.10/site-packages/mage_ai/orchestration/db/__init__.py\", line 149, in func_with_rollback\n    return func(*args, **kwargs)\n", "  File \"/usr/local/lib/python3.10/site-packages/mage_ai/orchestration/pipeline_scheduler_original.py\", line 182, in start\n    self.schedule()\n", "  File \"/usr/local/lib/python3.10/site-packages/mage_ai/orchestration/db/__init__.py\", line 149, in func_with_rollback\n    return func(*args, **kwargs)\n", "  File \"/usr/local/lib/python3.10/site-packages/mage_ai/orchestration/pipeline_scheduler_original.py\", line 319, in schedule\n    self.__schedule_blocks(block_runs)\n", "  File \"/usr/local/lib/python3.10/site-packages/mage_ai/orchestration/pipeline_scheduler_original.py\", line 581, in __schedule_blocks\n    job_manager.add_job(\n", "  File \"/usr/local/lib/python3.10/site-packages/mage_ai/orchestration/job_manager.py\", line 27, in add_job\n    self.queue.enqueue(job_id, target, *args, **kwargs)\n", "  File \"/usr/local/lib/python3.10/site-packages/mage_ai/orchestration/queue/process_queue.py\", line 107, in enqueue\n    self.start_worker_pool()\n", "  File \"/usr/local/lib/python3.10/site-packages/mage_ai/orchestration/queue/process_queue.py\", line 173, in start_worker_pool\n    self.worker_pool_proc.start()\n", "  File \"/usr/local/lib/python3.10/multiprocessing/process.py\", line 121, in start\n    self._popen = self._Popen(self)\n", "  File \"/usr/local/lib/python3.10/multiprocessing/context.py\", line 224, in _Popen\n    return _default_context.get_context().Process._Popen(process_obj)\n", "  File \"/usr/local/lib/python3.10/multiprocessing/context.py\", line 281, in _Popen\n    return Popen(process_obj)\n", "  File \"/usr/local/lib/python3.10/multiprocessing/popen_fork.py\", line 19, in __init__\n    self._launch(process_obj)\n", "  File \"/usr/local/lib/python3.10/multiprocessing/popen_fork.py\", line 71, in _launch\n    code = process_obj._bootstrap(parent_sentinel=child_r)\n", "  File \"/usr/local/lib/python3.10/multiprocessing/process.py\", line 314, in _bootstrap\n    self.run()\n", "  File \"/usr/local/lib/python3.10/multiprocessing/process.py\", line 108, in run\n    self._target(*self._args, **self._kwargs)\n", "  File \"/usr/local/lib/python3.10/site-packages/mage_ai/orchestration/queue/process_queue.py\", line 275, in poll_job_and_execute\n    worker.start()\n", "  File \"/usr/local/lib/python3.10/multiprocessing/process.py\", line 121, in start\n    self._popen = self._Popen(self)\n", "  File \"/usr/local/lib/python3.10/multiprocessing/context.py\", line 224, in _Popen\n    return _default_context.get_context().Process._Popen(process_obj)\n", "  File \"/usr/local/lib/python3.10/multiprocessing/context.py\", line 281, in _Popen\n    return Popen(process_obj)\n", "  File \"/usr/local/lib/python3.10/multiprocessing/popen_fork.py\", line 19, in __init__\n    self._launch(process_obj)\n", "  File \"/usr/local/lib/python3.10/multiprocessing/popen_fork.py\", line 71, in _launch\n    code = process_obj._bootstrap(parent_sentinel=child_r)\n", "  File \"/usr/local/lib/python3.10/multiprocessing/process.py\", line 314, in _bootstrap\n    self.run()\n", "  File \"/usr/local/lib/python3.10/site-packages/newrelic/api/background_task.py\", line 117, in wrapper\n    return wrapped(*args, **kwargs)\n", "  File \"/usr/local/lib/python3.10/site-packages/mage_ai/orchestration/queue/process_queue.py\", line 240, in run\n    start_session_and_run(args[1], *args[2], **args[3])\n", "  File \"/usr/local/lib/python3.10/site-packages/mage_ai/orchestration/db/process.py\", line 15, in start_session_and_run\n    results = target(*args)\n", "  File \"/usr/local/lib/python3.10/site-packages/mage_ai/orchestration/pipeline_scheduler_original.py\", line 1105, in run_block\n    return ExecutorFactory.get_block_executor(\n", "  File \"/usr/local/lib/python3.10/site-packages/mage_ai/data_preparation/executors/block_executor.py\", line 639, in execute\n    on_failure(\n", "  File \"/usr/local/lib/python3.10/site-packages/mage_ai/orchestration/db/__init__.py\", line 149, in func_with_rollback\n    return func(*args, **kwargs)\n", "  File \"/usr/local/lib/python3.10/site-packages/mage_ai/orchestration/pipeline_scheduler_original.py\", line 415, in on_block_failure\n    self.logger.exception(\n", "  File \"/usr/local/lib/python3.10/site-packages/mage_ai/data_preparation/logging/logger.py\", line 30, in exception\n    self.__send_message('exception', message, **kwargs)\n", "  File \"/usr/local/lib/python3.10/site-packages/mage_ai/data_preparation/logging/logger.py\", line 59, in __send_message\n    data['error_stack'] = traceback.format_stack(),\n"]], "error_stacktrace": ["Pipeline execution failed at stage extract when processing package 1713119017.476216 with exception:\n\n<class 'dlt.extract.exceptions.ResourceExtractionError'>\nIn processing pipe src_daily_standings: extraction of resource src_daily_standings in generator load_daily_standings caused an exception: ('Connection aborted.', RemoteDisconnected('Remote end closed connection without response'))"]}
Traceback (most recent call last):
  File "/usr/local/lib/python3.10/site-packages/urllib3/connectionpool.py", line 715, in urlopen
    httplib_response = self._make_request(
  File "/usr/local/lib/python3.10/site-packages/urllib3/connectionpool.py", line 467, in _make_request
    six.raise_from(e, None)
  File "<string>", line 3, in raise_from
  File "/usr/local/lib/python3.10/site-packages/urllib3/connectionpool.py", line 462, in _make_request
    httplib_response = conn.getresponse()
  File "/usr/local/lib/python3.10/http/client.py", line 1375, in getresponse
    response.begin()
  File "/usr/local/lib/python3.10/http/client.py", line 318, in begin
    version, status, reason = self._read_status()
  File "/usr/local/lib/python3.10/http/client.py", line 287, in _read_status
    raise RemoteDisconnected("Remote end closed connection without"
http.client.RemoteDisconnected: Remote end closed connection without response

During handling of the above exception, another exception occurred:

Traceback (most recent call last):
  File "/usr/local/lib/python3.10/site-packages/requests/adapters.py", line 486, in send
    resp = conn.urlopen(
  File "/usr/local/lib/python3.10/site-packages/urllib3/connectionpool.py", line 799, in urlopen
    retries = retries.increment(
  File "/usr/local/lib/python3.10/site-packages/urllib3/util/retry.py", line 550, in increment
    raise six.reraise(type(error), error, _stacktrace)
  File "/usr/local/lib/python3.10/site-packages/urllib3/packages/six.py", line 769, in reraise
    raise value.with_traceback(tb)
  File "/usr/local/lib/python3.10/site-packages/urllib3/connectionpool.py", line 715, in urlopen
    httplib_response = self._make_request(
  File "/usr/local/lib/python3.10/site-packages/urllib3/connectionpool.py", line 467, in _make_request
    six.raise_from(e, None)
  File "<string>", line 3, in raise_from
  File "/usr/local/lib/python3.10/site-packages/urllib3/connectionpool.py", line 462, in _make_request
    httplib_response = conn.getresponse()
  File "/usr/local/lib/python3.10/http/client.py", line 1375, in getresponse
    response.begin()
  File "/usr/local/lib/python3.10/http/client.py", line 318, in begin
    version, status, reason = self._read_status()
  File "/usr/local/lib/python3.10/http/client.py", line 287, in _read_status
    raise RemoteDisconnected("Remote end closed connection without"
urllib3.exceptions.ProtocolError: ('Connection aborted.', RemoteDisconnected('Remote end closed connection without response'))

During handling of the above exception, another exception occurred:

Traceback (most recent call last):
  File "/usr/local/lib/python3.10/site-packages/dlt/extract/pipe.py", line 837, in _get_source_item
    if (item := next(gen)) is not None:
  File "/home/src/./mage_nba_watchability_index/utils/dlt_resources/dlt_nba.py", line 151, in load_daily_standings
    ec = sb.ScoreboardV2(day_offset=-day_offset).east_conf_standings_by_day.get_data_frame()
  File "/usr/local/lib/python3.10/site-packages/nba_api/stats/endpoints/scoreboardv2.py", line 159, in __init__
    self.get_request()
  File "/usr/local/lib/python3.10/site-packages/nba_api/stats/endpoints/scoreboardv2.py", line 162, in get_request
    self.nba_response = NBAStatsHTTP().send_api_request(
  File "/usr/local/lib/python3.10/site-packages/nba_api/library/http.py", line 146, in send_api_request
    response = requests.get(
  File "/usr/local/lib/python3.10/site-packages/requests/api.py", line 73, in get
    return request("get", url, params=params, **kwargs)
  File "/usr/local/lib/python3.10/site-packages/requests/api.py", line 59, in request
    return session.request(method=method, url=url, **kwargs)
  File "/usr/local/lib/python3.10/site-packages/requests/sessions.py", line 589, in request
    resp = self.send(prep, **send_kwargs)
  File "/usr/local/lib/python3.10/site-packages/requests/sessions.py", line 703, in send
    r = adapter.send(request, **kwargs)
  File "/usr/local/lib/python3.10/site-packages/requests/adapters.py", line 501, in send
    raise ConnectionError(err, request=request)
requests.exceptions.ConnectionError: ('Connection aborted.', RemoteDisconnected('Remote end closed connection without response'))

The above exception was the direct cause of the following exception:

Traceback (most recent call last):
  File "/usr/local/lib/python3.10/site-packages/dlt/pipeline/pipeline.py", line 391, in extract
    self._extract_source(extract_step, source, max_parallel_items, workers)
  File "/usr/local/lib/python3.10/site-packages/dlt/pipeline/pipeline.py", line 1028, in _extract_source
    load_id = extract.extract(source, max_parallel_items, workers)
  File "/usr/local/lib/python3.10/site-packages/dlt/extract/extract.py", line 341, in extract
    self._extract_single_source(
  File "/usr/local/lib/python3.10/site-packages/dlt/extract/extract.py", line 271, in _extract_single_source
    for pipe_item in pipes:
  File "/usr/local/lib/python3.10/site-packages/dlt/extract/pipe.py", line 605, in __next__
    pipe_item = self._get_source_item()
  File "/usr/local/lib/python3.10/site-packages/dlt/extract/pipe.py", line 863, in _get_source_item
    raise ResourceExtractionError(pipe.name, gen, str(ex), "generator") from ex
dlt.extract.exceptions.ResourceExtractionError: In processing pipe src_daily_standings: extraction of resource src_daily_standings in generator load_daily_standings caused an exception: ('Connection aborted.', RemoteDisconnected('Remote end closed connection without response'))

The above exception was the direct cause of the following exception:

Traceback (most recent call last):
  File "/usr/local/lib/python3.10/site-packages/mage_ai/data_preparation/executors/block_executor.py", line 612, in execute
    result = __execute_with_retry()
  File "/usr/local/lib/python3.10/site-packages/mage_ai/shared/retry.py", line 54, in retry_func
    raise e
  File "/usr/local/lib/python3.10/site-packages/mage_ai/shared/retry.py", line 38, in retry_func
    return func(*args, **kwargs)
  File "/usr/local/lib/python3.10/site-packages/mage_ai/data_preparation/executors/block_executor.py", line 587, in __execute_with_retry
    return self._execute(
  File "/usr/local/lib/python3.10/site-packages/mage_ai/data_preparation/executors/block_executor.py", line 1075, in _execute
    result = self.block.execute_sync(
  File "/usr/local/lib/python3.10/site-packages/mage_ai/data_preparation/models/block/__init__.py", line 1312, in execute_sync
    raise err
  File "/usr/local/lib/python3.10/site-packages/mage_ai/data_preparation/models/block/__init__.py", line 1221, in execute_sync
    output = self.execute_block(
  File "/usr/local/lib/python3.10/site-packages/mage_ai/data_preparation/models/block/__init__.py", line 1527, in execute_block
    outputs = self._execute_block(
  File "/usr/local/lib/python3.10/site-packages/mage_ai/data_preparation/models/block/__init__.py", line 1683, in _execute_block
    outputs = self.execute_block_function(
  File "/usr/local/lib/python3.10/site-packages/mage_ai/data_preparation/models/block/__init__.py", line 1722, in execute_block_function
    output = block_function_updated(*input_vars, **global_vars)
  File "<string>", line 58, in load_data
  File "/usr/local/lib/python3.10/site-packages/dlt/pipeline/pipeline.py", line 193, in _wrap
    step_info = f(self, *args, **kwargs)
  File "/usr/local/lib/python3.10/site-packages/dlt/pipeline/pipeline.py", line 238, in _wrap
    return f(self, *args, **kwargs)
  File "/usr/local/lib/python3.10/site-packages/dlt/pipeline/pipeline.py", line 619, in run
    self.extract(
  File "/usr/local/lib/python3.10/site-packages/dlt/pipeline/pipeline.py", line 193, in _wrap
    step_info = f(self, *args, **kwargs)
  File "/usr/local/lib/python3.10/site-packages/dlt/pipeline/pipeline.py", line 164, in _wrap
    rv = f(self, *args, **kwargs)
  File "/usr/local/lib/python3.10/site-packages/dlt/pipeline/pipeline.py", line 151, in _wrap
    return f(self, *args, **kwargs)
  File "/usr/local/lib/python3.10/site-packages/dlt/pipeline/pipeline.py", line 238, in _wrap
    return f(self, *args, **kwargs)
  File "/usr/local/lib/python3.10/site-packages/dlt/pipeline/pipeline.py", line 403, in extract
    raise PipelineStepFailed(
dlt.pipeline.exceptions.PipelineStepFailed: Pipeline execution failed at stage extract when processing package 1713119017.476216 with exception:

<class 'dlt.extract.exceptions.ResourceExtractionError'>
In processing pipe src_daily_standings: extraction of resource src_daily_standings in generator load_daily_standings caused an exception: ('Connection aborted.', RemoteDisconnected('Remote end closed connection without response'))
2024-04-14T18:24:51 {"cpu": 0.38671875, "cpu_total": 8, "cpu_usage": 0.04833984375, "memory": 3171.0, "memory_total": 9922.0, "memory_usage": 0.31959282402741385, "pipeline_run_id": 6, "pipeline_schedule_id": 6, "pipeline_uuid": "seed_bq", "hostname": "ee16a9cfd313", "level": "INFO", "message": "Pipeline seed_bq for run 6 in schedule 6 is alive.", "timestamp": 1713119091.163162, "uuid": "2eb7b0cffde4458f95189bf9d10c0854"}
